Workbook

Sheet AÑO 2026
A1: INCLUIDO | B1: HIPOTECA 1 | C1: 800 | G1: SANTANDER | H1: KUTXA | I1: N26 | L1: INDEXA | M1: FONDO JBN | N1: FONDO YUG | O1: TOTAL INVERTIDO | R1: GRAN TOTAL | T1: OBJETIVO | U1: CUOTAS | V1: HACIENDA | X1: AHORRADO | Y1: RESTO HIPOTECA | Z1: 66500 | AA1: OBJETIVO | AB1: CUOTAS | AC1: AHORRADO | AD1: RESTO LOCAL | AE1: 29500
B2: HIPOTECA 2 | C2: 500 | F2: 46023 | G2: 6070.02 | H2: 3232.92 | I2: 15.314 | J2: =G2+H2+I2 -> 9318.254 | L2: 0 | M2: 1705.37 | N2: 1905.37 | O2: =SUM(L2:N2) -> 3610.74 | R2: =I2+O2 -> 3626.054 | S2: 1 | T2: AÑO 2025 | U2: 7000 | W2: 15400 | Y2: =Z1-U2-V2-W2-X2 -> 44100 | AA2: AÑO 2025 | AB2: 6000 | AD2: =AE1-AB2-AC2 -> 23500
B3: ALQUILER VITORIA | C3: 275 | F3: 46387 | G3: =Q15 -> 3605.67 | H3: =Q16 -> 3597.37 | I3: =Q17 -> 2269.984 | J3: =G3+H3+I3 -> 9473.024 | L3: 0 | M3: =Q18 -> 2122.59 | N3: =Q19 -> 2322.59 | O3: =SUM(L3:N3) -> 4445.18 | R3: =I3+O3 -> 6715.164 | S3: 2 | T3: AÑO 2026 | U3: 8400 | W3: 5000 | Y3: =Y2-U3-V3-W3-X3 -> 30700 | AA3: AÑO 2026 | AB3: 6000 | AD3: =AD2-AB3-AC3 -> 17500
B4: OBRAS LOCAL 6600 | C4: 550 | F4: AHORRO | G4: =G3-G2 -> -2464.35 | H4: =H3-H2 -> 364.45 | I4: =I3-I2 -> 2254.67 | J4: =G4+H4+I4 -> 154.77 | L4: =L3-L2 -> 0 | M4: =M3-M2 -> 417.22 | N4: =N3-N2 -> 417.22 | O4: =SUM(L4:N4) -> 834.44 | S4: 3 | T4: AÑO 2027 | U4: 8800 | W4: 5000 | Y4: =Y3-U4-V4-W4-X4 -> 16900 | AA4: AÑO 2027 | AB4: 6000 | AD4: =AD3-AB4-AC4 -> 11500
C5: =SUM(C1:C4) -> 2125 | E5: SIN CONTAR AMORTIZACION | F5: AHORRO * | G5: =G3-G2+F92+J92 -> -2464.35 | H5: =H3-H2 -> 364.45 | I5: =I3-I2 -> 2254.67 | J5: =G5+H5+I5 -> 154.77 | L5: =L3-L2 -> 0 | M5: =M3-M2 -> 417.22 | N5: =N3-N2 -> 417.22 | O5: =SUM(L5:N5) -> 834.44 | R5: =I5+O5 -> 3089.11 | S5: 4 | T5: AÑO 2028 | U5: 9300 | W5: 7500 | Y5: =Y4-U5-V5-W5-X5 -> 100 | AA5: AÑO 2028 | AB5: 9300 | AD5: =AD4-AB5-AC5 -> 2200
S6: 5 | T6: AÑO 2029 | U6: 9600 | Y6: =Y5-U6-V6-W6-X6 -> -9500 | AA6: AÑO 2029 | AB6: 9600 | AD6: =AD5-AB6-AC6 -> -7400
S7: 6 | T7: AÑO 2030 | U7: 6003 | Y7: =Y6-U7-V7-W7-X7 -> -15503 | AA7: AÑO 2030 | AB7: 6003 | AD7: =AD6-AB7-AC7 -> -13403
B9: CASH EN SANTANDER A PRIMEROS DE MES | F9: =G2 -> 6070.02 | G9: =F15 -> 5146.28 | H9: =G15 -> 6081.17 | I9: =H15 -> 4416.61 | J9: =I15 -> 5348.76 | K9: =J15 -> 5485.05 | L9: =K15 -> 3697.18 | M9: =L15 -> 7035.03 | N9: =M15 -> 4500.9 | ... Q9: =P15 -> 3697.51 | R9: =SUM(F9:Q9) -> 58783.77
B10: CASH EN KUTXA A PRIMEROS DE MES | F10: =H2 -> 3232.92 | G10: =F16 -> 3912.66 | H10: =G16 -> 3646.6 | I10: =H16 -> 3463.17 | J10: =I16 -> 1020.92 | K10: =J16 -> 2974.03 | L10: =K16 -> 3383.77 | M10: =L16 -> 3405.97 | N10: =M16 -> 1545.24 | ... Q10: =P16 -> 3269.57 | R10: =SUM(F10:Q10) -> 34698.34
B11: CASH EN N26 A PRIMEROS DE MES | F11: =I2 -> 15.314 | G11: =F17 -> 470.874 | H11: =G17 -> 269.884 | I11: =H17 -> 629.884 | J11: =I17 -> 1128.834 | K11: =J17 -> 1321.414 | L11: =K17 -> 1685.004 | M11: =L17 -> 1871.044 | N11: =M17 -> 2269.984 | ... Q11: =P17 -> 2269.984 | R11: =SUM(F11:Q11) -> 16472.188 | T11: A primeros de 2028 tendremos pendiente 6.800€
B12: CASH EN EPSV KUTXA JULIO PRIMEROS DE MES | F12: =M2 -> 1705.37 | G12: =F18 -> 1739.24 | H12: =G18 -> 1774.09 | I12: =H18 -> 1808.94 | J12: =I18 -> 1843.79 | K12: =J18 -> 1878.64 | L12: =K18 -> 1913.49 | M12: =L18 -> 1948.34 | N12: =M18 -> 1983.19 | ... Q12: =P18 -> 2087.74 | R12: =SUM(F12:Q12) -> 22753.76
B13: CASH EN EPSV KUTXA YOLANDA PRIMEROS DE MES | F13: =N2 -> 1905.37 | G13: =F19 -> 1939.24 | H13: =G19 -> 1974.09 | I13: =H19 -> 2008.94 | J13: =I19 -> 2043.79 | K13: =J19 -> 2078.64 | L13: =K19 -> 2113.49 | M13: =L19 -> 2148.34 | N13: =M19 -> 2183.19 | ... Q13: =P19 -> 2287.74 | R13: =SUM(F13:Q13) -> 25153.76
F14: =SUM(F9:F11) -> 9318.254 | G14: =SUM(G9:G11) -> 9529.814 | H14: =SUM(H9:H11) -> 9997.654 | I14: =SUM(I9:I11) -> 8509.664 | J14: =SUM(J9:J11) -> 7498.514 | K14: =SUM(K9:K11) -> 9780.494 | L14: =SUM(L9:L11) -> 8765.954 | M14: =SUM(M9:M11) -> 12312.044 | ... Q14: =SUM(Q9:Q11) -> 9237.064
B15: CASH EN SANTANDER FIN DE MES | F15: =F9+F150-F151 -> 5146.28 | G15: =G9+G150-G151 -> 6081.17 | H15: =H9+H150-H151 -> 4416.61 | I15: =I9+I150-I151 -> 5348.76 | J15: =J9+J150-J151 -> 5485.05 | K15: =K9+K150-K151 -> 3697.18 | L15: =L9+L150-L151 -> 7035.03 | M15: =M9+M150-M151 -> 4500.9 | ... Q15: =Q9+Q150-Q151 -> 3605.67 | R15: =SUM(F15:Q15) -> 56319.42 | S15: =R15-R9 -> -2464.35 | T15: =S15+S16+S17 -> 154.77 | U15: =T18+T15 -> 989.21
B16: CASH EN KUTXA FIN DE MES | F16: =F10+F153-F154 -> 3912.66 | G16: =G10+G153-G154 -> 3646.6 | H16: =H10+H153-H154 -> 3463.17 | I16: =I10+I153-I154 -> 1020.92 | J16: =J10+J153-J154 -> 2974.03 | K16: =K10+K153-K154 -> 3383.77 | L16: =L10+L153-L154 -> 3405.97 | M16: =M10+M153-M154 -> 1545.24 | ... Q16: =Q10+Q153-Q154 -> 3597.37 | R16: =SUM(F16:Q16) -> 35062.79 | S16: =R16-R10 -> 364.45
B17: CASH EN N26 A FIN DE MES | F17: =F11+F156-F157 -> 470.874 | G17: =G11+G156-G157 -> 269.884 | H17: =H11+H156-H157 -> 629.884 | I17: =I11+I156-I157 -> 1128.834 | J17: =J11+J156-J157 -> 1321.414 | K17: =K11+K156-K157 -> 1685.004 | L17: =L11+L156-L157 -> 1871.044 | M17: =M11+M156-M157 -> 2269.984 | ... Q17: =Q11+Q156-Q157 -> 2269.984 | R17: =SUM(F17:Q17) -> 18726.858 | S17: =R17-R11 -> 2254.67
B18: CASH EN EPSV KUTXA JULIO FIN DE MES | F18: =F12+F93+F117 -> 1739.24 | G18: =G12+G93+G117 -> 1774.09 | H18: =H12+H93+H117 -> 1808.94 | I18: =I12+I93+I117 -> 1843.79 | J18: =J12+J93+J117 -> 1878.64 | K18: =K12+K93+K117 -> 1913.49 | L18: =L12+L93+L117 -> 1948.34 | M18: =M12+M93+M117 -> 1983.19 | ... Q18: =Q12+Q93+Q117 -> 2122.59 | R18: =SUM(F18:Q18) -> 23170.98 | S18: =R18-R12 -> 417.22 | T18: =S18+S19 -> 834.44
B19: CASH EN EPSV KUTXA YOLANDA FIN DE MES | F19: =F13+F93+F118 -> 1939.24 | G19: =G13+G93+G118 -> 1974.09 | H19: =H13+H93+H118 -> 2008.94 | I19: =I13+I93+I118 -> 2043.79 | J19: =J13+J93+J118 -> 2078.64 | K19: =K13+K93+K118 -> 2113.49 | L19: =L13+L93+L118 -> 2148.34 | M19: =M13+M93+M118 -> 2183.19 | ... Q19: =Q13+Q93+Q118 -> 2322.59 | R19: =SUM(F19:Q19) -> 25570.98 | S19: =R19-R13 -> 417.22
F20: =SUM(F15:F17) -> 9529.814 | G20: =SUM(G15:G17) -> 9997.654 | H20: =SUM(H15:H17) -> 8509.664 | I20: =SUM(I15:I17) -> 7498.514 | J20: =SUM(J15:J17) -> 9780.494 | K20: =SUM(K15:K17) -> 8765.954 | L20: =SUM(L15:L17) -> 12312.044 | M20: =SUM(M15:M17) -> 8316.124 | ... Q20: =SUM(Q15:Q17) -> 9473.024
A21: BANCO | C21: CONCEPTO | D21: DIA | E21: OBSERVACIONES | F21: 2026 | R21: TOTAL
F23: ENERO | G23: FEBRERO | H23: MARZO | I23: ABRIL | J23: MAYO | K23: JUNIO | L23: JULIO | M23: AGOSTO | N23: SEPTIEMBRE | O23: OCTUBRE | P23: NOVIEMBRE | Q23: DICIEMBRE
F24: INGRESOS
A25: SANTANDER | B25: NOMINA JULIO | F25: 2277.03 | G25: 2295.28 | H25: 2330.61 | I25: 2365.91 | J25: 2365.91 | K25: 2348.24 | L25: 2365.91 | M25: 0 | N25: 2029.23 | O25: 2315.58 | P25: 2351.39 | Q25: 2055.39 | R25: =SUM(F25:Q25) -> 25100.48
A26: SANTANDER | B26: NOMINA JULIO 2 | H26: 214.96 | J26: 242.8 | L26: 2383.55 | P26: 0.19 | R26: =SUM(F26:Q26) -> 2841.5
A27: SANTANDER | B27: PAGA JULIO | J27: 0.2 | L27: 1965.82 | Q27: 1933.44 | R27: =SUM(F27:Q27) -> 3899.46
A28: SANTANDER | B28: OTROS INGRESOS | R28: =SUM(F28:Q28) -> 0
A29: SANTANDER | B29: DECLARACION JULIO | I29: 1963.96 | R29: =SUM(F29:Q29) -> 1963.96
A30: SANTANDER | B30: DECLARACION YOLANDA | I30: 1693.84 | R30: =SUM(F30:Q30) -> 1693.84
A31: SANTANDER | B31: GESTION COMUNIDAD | R31: =SUM(F31:Q31) -> 0
A32: SANTANDER | B32: TRASFERENCIA DESDE KUTXA | F32: =F119 -> 0 | G32: =G119 -> 0 | H32: =H119 -> 0 | I32: =I119 -> 0 | J32: =J119 -> 0 | K32: =K119 -> 0 | L32: =L119 -> 0 | M32: =M119 -> 0 | ... Q32: =Q119 -> 0 | R32: =SUM(F32:Q32) -> 0
A33: SANTANDER | B33: TRASFERENCIA DESDE N26 | F33: =F135 -> 0 | G33: =G135 -> 0 | H33: =H135 -> 0 | I33: =I135 -> 0 | J33: =J135 -> 0 | K33: =K135 -> 0 | L33: =L135 -> 0 | M33: =M135 -> 0 | ... Q33: =Q135 -> 0 | R33: =SUM(F33:Q33) -> 0 | S33: =SUM(R25:R33) -> 35499.24
A36: KUTXA | B36: NOMINA YOLANDA | F36: 0 | G36: 0 | H36: 0 | I36: 0 | J36: 4715 | K36: 0 | L36: 0 | M36: 0 | N36: 2357.5 | O36: 2357.5 | P36: 2357.5 | Q36: 2357.5 | R36: =SUM(F36:Q36) -> 14145
A37: KUTXA | B37: INGRESO OTROS. NOMINA COBRADA MES ANTERIOR | F37: 2357.5 | G37: 2357.5 | H37: 2357.5 | I37: 0 | J37: 0 | K37: 2357.5 | L37: 2357.5 | M37: 0 | N37: 0 | O37: 0 | P37: 0 | Q37: 0 | R37: =SUM(F37:Q37) -> 11787.5
A38: KUTXA | B38: TRASFERENCIA DESDE SANTANDER | F38: =F95 -> 0 | G38: =G95 -> 0 | H38: =H95 -> 500 | I38: =I95 -> 500 | J38: =J95 -> 500 | K38: =K95 -> 500 | L38: =L95 -> 500 | M38: =M95 -> 500 | ... Q38: =Q95 -> 500 | R38: =SUM(F38:Q38) -> 5000
A39: KUTXA | B39: TRASFERENCIA DESDE N26 | F39: =F136 -> 0 | G39: =G136 -> 0 | H39: =H136 -> 0 | I39: =I136 -> 0 | J39: =J136 -> 0 | K39: =K136 -> 0 | L39: =L136 -> 0 | M39: =M136 -> 0 | ... Q39: =Q136 -> 0 | R39: =SUM(F39:Q39) -> 0 | S39: =SUM(R36:R39) -> 30932.5
A41: N26 | B41: INGRESO OTROS | F41: 0 | G41: 0 | H41: 0 | I41: 0 | J41: 0 | K41: 0 | L41: 0 | M41: 0 | N41: 0 | O41: 0 | P41: 0 | Q41: 0 | R41: =SUM(F41:Q41) -> 0
A42: N26 | B42: TRASFERENCIA DESDE SANTANDER-1- IMPREVISTOS | F42: =F96 -> 1000 | G42: =G96 -> 0 | H42: =H96 -> 500 | I42: =I96 -> 500 | J42: =J96 -> 500 | K42: =K96 -> 500 | L42: =L96 -> 500 | M42: =M96 -> 500 | ... Q42: =Q96 -> 500 | R42: =SUM(F42:Q42) -> 6000
A43: N26 | B43: TRASFERENCIA DESDE SANTANDER-2-AHORROS | F43: =F97 -> 0 | G43: =G97 -> 0 | H43: =H97 -> 0 | I43: =I97 -> 0 | J43: =J97 -> 0 | K43: =K97 -> 0 | L43: =L97 -> 0 | M43: =M97 -> 0 | ... Q43: =Q97 -> 0 | R43: =SUM(F43:Q43) -> 0
A44: N26 | B44: TRASFERENCIA DESDE KUTXA | F44: =F120 -> 0 | G44: =G120 -> 0 | H44: =H120 -> 0 | I44: =I120 -> 0 | J44: =J120 -> 0 | K44: =K120 -> 0 | L44: =L120 -> 0 | M44: =M120 -> 0 | ... Q44: =Q120 -> 0 | R44: =SUM(F44:Q44) -> 0 | S44: =SUM(R41:R44) -> 6000
R45: =R25+R26+R27+R28+R29+R30+R31+R36+R37+R41 -> 61431.74 | S45: =S33+S39+S44 -> 72431.74 | T45: * INCLUYENDO INGRESOS DE OTRAS CUENTAS
...

Sheet GASTOS 
A1: SANTANDER | B1: ENERO | H1: FEBRERO | N1: MARZO | T1: ABRIL | Z1: MAYO | AF1: JUNIO | AL1: JULIO | AR1: AGOSTO | AX1: SEPTIEMBRE | BD1: OCTUBRE | BJ1: NOVIEMBRE | BP1: DICIEMBRE
B2: DIA | C2: TIENDA | D2: CONCEPTO | E2: CATEGORIA | F2: CANTIDAD | G2: BANCO | H2: DIA | I2: TIENDA | J2: CONCEPTO | K2: CATEGORIA | L2: CANTIDAD | M2: BANCO | N2: DIA | O2: TIENDA | P2: CONCEPTO | Q2: CATEGORIA | R2: CANTIDAD | S2: BANCO | T2: DIA | U2: TIENDA | V2: CONCEPTO | W2: CATEGORIA | X2: CANTIDAD | Y2: BANCO | Z2: DIA | AA2: TIENDA | AB2: CONCEPTO | AC2: CATEGORIA | AD2: CANTIDAD | AE2: BANCO | AF2: DIA | AG2: TIENDA | AH2: CONCEPTO | AI2: CATEGORIA | AJ2: CANTIDAD | AK2: BANCO | AL2: DIA | AM2: TIENDA | AN2: CONCEPTO | AO2: CATEGORIA | AP2: CANTIDAD | AQ2: BANCO | AR2: DIA | AS2: TIENDA | AT2: CONCEPTO | AU2: CATEGORIA | AV2: CANTIDAD | AW2: BANCO | AX2: DIA | AY2: TIENDA | AZ2: CONCEPTO | BA2: CATEGORIA | BB2: CANTIDAD | BC2: BANCO | BD2: DIA | BE2: TIENDA | BF2: CONCEPTO | BG2: CATEGORIA | BH2: CANTIDAD | BI2: BANCO | BJ2: DIA | BK2: TIENDA | BL2: CONCEPTO | BM2: CATEGORIA | BN2: CANTIDAD | BO2: BANCO | BP2: DIA | BQ2: TIENDA | BR2: CONCEPTO | BS2: CATEGORIA | BT2: CANTIDAD | BU2: BANCO
B3: 10 | C3: LEROY MERLIN | D3: MUEBLE Y GRIFERIA BAÑO | F3: 353.96 | G3: S | T3: 46123 | U3: DIA | X3: 64.81 | Y3: K | Z3: 46147 | AA3: PAYPAL | AB3: SILLA ESCRITORIO | AD3: 36.42 | AE3: S | AL3: 46209 | AM3: DEPORVILLAGE | AN3: REGALO YOLI | AP3: 152.85 | AQ3: S | AR3: 46235 | AS3: ARRATE | AV3: 74.34
B4: 46038 | C4: GOOGLE ONE | D4: DEVOLUCION | F4: -19.71 | G4: S | I4: Aliexpress | L4: 0.99 | N4: 46091 | O4: Toogoogtogo | R4: 5.99 | S4: K | T4: 46129 | U4: TEMU | X4: 25.18 | Y4: K | Z4: 46153 | AA4: CLAUDE? | AD4: 23.1 | AE4: S | AF4: 46192 | AG4: PAYPAL | AH4: JUEGO EPIC | AJ4: 0.89 | AK4: S | AL4: 46226 | AM4: JUSTEAT | AP4: 25.25 | AQ4: S | AR4: 46237 | AS4: TEMU | AT4: CAMISETA | AV4: 11.64 | AW4: K
B5: 46038 | C5: GOOGLE ONE | D5: PRO | F5: 10.99 | G5: S | N5: 46092 | O5: Spotify | R5: 6 | S5: S | T5: 46130 | U5: BUENOS AIRES | X5: 4.6 | Y5: K | Z5: 46157 | AA5: AMAZON | AB5: GEL DECAPANTE | AD5: 35.99 | AE5: S | AF5: 46202 | AG5: PAYPAL | AH5: SILLA TIK TOK | AJ5: 37.41 | AK5: S | AL5: 46228 | AM5: WIKILOC | AP5: 9.99 | AQ5: S | AR5: 46238 | AS5: JUSTEAT | AV5: 16.71 | AW5: K
B6: 46041 | C6: TEMU | D6: PARAGUAS Y PARCHES | F6: 23.09 | G6: K | I6: just eat | L6: 21.25 | N6: 46105 | O6: JustEat | R6: 32.15 | S6: K | T6: 46139 | U6: RETIRADA | V6: RIFF | X6: 900 | Y6: S | Z6: 46160 | AA6: AMAZON | AB6: PELICULA DEMOLICION | AD6: 3.99 | AE6: S | AR6: 46247 | AS6: TIK TOK SHOP | AT6: TOALLA | AV6: 9.94 | AW6: K
B7: 46048 | C7: TRASPASO A REVOLUT | F7: 136.04 | G7: K | T7: 46140 | U7: RETIRADA | V7: RIFF | X7: 900 | Y7: S | Z7: 46168 | AA7: JUST-EAT | AD7: 19.75 | AE7: S | AR7: 46248 | AS7: EROSKI | AV7: 35.25 | AW7: K
T8: 46141 | U8: RETIRADA | V8: RIFF | X8: 900 | Y8: S | AR8: 46259 | AS8: JUSTEAT | AV8: 19.75 | AW8: K
AR9: 46260 | AS9: PARFOIS | AV9: 25.99 | AW9: K
AF14: 46178 | AG14: JUANCAR | AH14: ADELANTO RIFF | AI14: RETIRADA EFECTIVO | AJ14: 800 | AK14: S
O15: REONOR | P15: PLADUR | R15: 1600 | S15: S | AF15: 46182 | AG15: JUANCAR | AH15: ADELANTO RIFF | AI15: RETIRADA EFECTIVO | AJ15: 500 | AK15: S | AN15: RIFF | AO15: RETIRADAS EFECTIVO | AP15: 1000 | AQ15: S
F17: =SUM(F2:F16) -> 504.37 | L17: =SUM(L3:L16) -> 22.24 | R17: =SUM(R3:R16) -> 1644.14 | X17: =SUM(X3:X16) -> 2794.59 | AD17: =SUM(AD3:AD16) -> 119.25 | AJ17: =SUM(AJ3:AJ16) -> 1338.3 | AP17: =SUM(AP2:AP16) -> 1188.09 | AV17: =SUM(AV2:AV16) -> 193.62 | BB17: =SUM(BB2:BB16) -> 0 | BH17: =SUM(BH3:BH16) -> 0 | BN17: =SUM(BN2:BN16) -> 0 | BT17: =SUM(BT2:BT16) -> 0
AD19: =X19+AD18 -> 0
A20: KUTXA | B20: ENERO | H20: FEBRERO | N20: MARZO | T20: ABRIL | Z20: MAYO | AF20: JUNIO | AL20: JULIO | AR20: AGOSTO | AX20: SEPTIEMBRE | BD20: OCTUBRE | BJ20: NOVIEMBRE | BP20: DICIEMBRE
B21: DIA | C21: TIENDA | D21: CONCEPTO | E21: CATEGORIA | F21: CANTIDAD | G21: BANCO | H21: DIA | I21: TIENDA | J21: CONCEPTO | K21: CATEGORIA | L21: CANTIDAD | M21: BANCO | N21: DIA | O21: TIENDA | P21: CONCEPTO | Q21: CATEGORIA | R21: CANTIDAD | S21: BANCO | T21: DIA | U21: TIENDA | V21: CONCEPTO | W21: CATEGORIA | X21: CANTIDAD | Y21: BANCO | Z21: DIA | AA21: TIENDA | AB21: CONCEPTO | AC21: CATEGORIA | AD21: CANTIDAD | AE21: BANCO | AF21: DIA | AG21: TIENDA | AH21: CONCEPTO | AI21: CATEGORIA | AJ21: CANTIDAD | AK21: BANCO | AL21: DIA | AM21: TIENDA | AN21: CONCEPTO | AO21: CATEGORIA | AP21: CANTIDAD | AQ21: BANCO | AR21: DIA | AS21: TIENDA | AT21: CONCEPTO | AU21: CATEGORIA | AV21: CANTIDAD | AW21: BANCO | AX21: DIA | AY21: TIENDA | AZ21: CONCEPTO | BA21: CATEGORIA | BB21: CANTIDAD | BC21: BANCO | BD21: DIA | BE21: TIENDA | BF21: CONCEPTO | BG21: CATEGORIA | BH21: CANTIDAD | BI21: BANCO | BJ21: DIA | BK21: TIENDA | BL21: CONCEPTO | BM21: CATEGORIA | BN21: CANTIDAD | BO21: BANCO | BP21: DIA | BQ21: TIENDA | BR21: CONCEPTO | BS21: CATEGORIA | BT21: CANTIDAD | BU21: BANCO
B22: 46024 | C22: BIZUM | D22: PELUQUERIA | F22: 87 | G22: K | H22: 46054 | I22: GASTOS TARJETA | L22: 585.13 | N22: 46082 | O22: GASTOS TARJETA | R22: 559.1 | T22: 46113 | U22: PAGO CAJERO | X22: 100 | Y22: K | Z22: 46143 | AA22: GASTOS TARJETA | AD22: 26.74 | AF22: 46174 | AG22: GASTOS TARJETA | AJ22: 94.77 | AL22: 46204 | AM22: GASTOS TARJETA | AP22: 109.82 | AR22: 46235 | AS22: PAGO CAJERO | AV22: 150 | AW22: K
B23: 46025 | C23: PAGO CAJERO | F23: 50 | G23: K | H23: 46054 | I23: PAGO CAJERO | L23: 50 | M23: K | N23: 46085 | O23: PAGO CAJERO | R23: 50 | S23: K | T23: 46119 | U23: PAGO CAJERO | X23: 100 | Y23: K | Z23: 46143 | AA23: PAGO CAJERO | AD23: 100 | AE23: K | AF23: 46174 | AG23: GASTOS TARJETA | AJ23: 155.28 | AL23: 46206 | AM23: GASTOS TARJETA | AP23: 264.08 | AR23: 46238 | AS23: PAGO CAJERO | AV23: 50 | AW23: K
B24: 46031 | C24: PAGO CAJERO | F24: 100 | G24: K | H24: 46058 | I24: PAGO CAJERO | L24: 50 | M24: K | N24: 46085 | O24: AMAIA | R24: 54.45 | S24: K | T24: 46121 | U24: IMPUESTO CIRCULACION | X24: 88 | Y24: K | Z24: 46146 | AA24: BIZUM | AB24: IBUR ERREKA | AD24: 70 | AE24: K | AF24: 46175 | AG24: op.net | AJ24: 16.4 | AK24: K | AL24: 46209 | AM24: GASTOS TARJETA | AP24: 182.79 | AR24: 46242 | AS24: PAGO CAJERO | AV24: 100 | AW24: K
B25: 46032 | C25: GASTOS TARJETA | F25: 271.72 | H25: 46060 | I25: BIZUM | J25: BAR VITORIA | L25: 4.9 | M25: K | N25: 46086 | O25: AMAIA | R25: 15.55 | S25: K | T25: 46122 | U25: BIZUM | X25: 10 | Y25: K | Z25: 46147 | AA25: PAGO CAJERO | AD25: 50 | AE25: K | AF25: 46176 | AG25: PAGO CAJERO | AJ25: 50 | AK25: K | AL25: 46213 | AM25: COCHE | AN25: PUESTA A PUNTO | AP25: 646.06 | AQ25: K | AR25: 46244 | AS25: GASTOS TARJETA | AV25: 122.08
B26: 46033 | C26: PAGO CAJERO | F26: 50 | G26: K | H26: 46061 | I26: PAGO CAJERO | L26: 50 | M26: K | N26: 46088 | O26: PAGO CAJERO | R26: 120 | S26: K | T26: 46123 | U26: EUSKALTEGI C2 | X26: 50 | Y26: K | Z26: 46147 | AA26: BIZUM | AB26: COMPRA DOS SEMANAS | AD26: 30 | AE26: K | AF26: 46178 | AG26: PAGO CAJERO | AJ26: 100 | AK26: K | AL26: 46214 | AM26: PAGO CAJERO | AP26: 100 | AQ26: K | AR26: 46244 | AS26: PAGO CAJERO | AV26: 50 | AW26: K
B27: 46039 | C27: PAGO CAJERO | F27: 100 | G27: K | H27: 46064 | I27: PAGO CAJERO | L27: 300 | M27: K | N27: 46090 | O27: PAGO CAJERO | R27: 50 | S27: K | T27: 46125 | U27: PAGO CAJERO | X27: 50 | Y27: K | Z27: 46149 | AA27: PAGO CAJERO | AD27: 50 | AE27: K | AF27: 46181 | AG27: PAGO CAJERO | AJ27: 50 | AK27: K | AL27: 46217 | AM27: PAGO CAJERO | AP27: 50 | AQ27: K | AR27: 46248 | AS27: PAGO CAJERO | AV27: 50 | AW27: K
B28: 46040 | C28: PAGO CAJERO | F28: 50 | G28: K | H28: 46068 | I28: FACTURA LUZ | L28: 12.9 | M28: K | N28: 46091 | O28: GALLETAS | R28: -3 | S28: K | T28: 46126 | U28: BIZUM | X28: 8 | Y28: K | Z28: 46149 | AA28: BIZUM | AB28: TOALLAS EVA | AD28: -12 | AE28: K | AF28: 46185 | AG28: PAGO CAJERO | AJ28: 50 | AK28: K | AL28: 46222 | AM28: COMIDA ZARAUTZ | AP28: 60 | AQ28: K | AR28: 46250 | AS28: GASTOS TARJETA | AV28: 133.22
B29: 46041 | C29: LUZ AMAIA | D29: PISO VITORIA | F29: 10 | G29: K | H29: 46070 | I29: PAGO CAJERO | L29: 40 | M29: K | N29: 46093 | O29: AMAIA | R29: 17 | S29: K | T29: 46129 | U29: PAGO CAJERO | X29: 100 | Y29: K | Z29: 46150 | AA29: TRASFERENCIA | AB29: DERRAMA URKI BAJO 9 | AD29: 549.95 | AE29: K | AF29: 46186 | AG29: PAGO CAJERO | AJ29: 100 | AK29: K | AL29: 46222 | AM29: GASTOS TARJETA | AP29: 343.96 | AR29: 46251 | AS29: PAGO CAJERO | AV29: 50 | AW29: K
B30: 46042 | C30: INGRESO NIÑAS LONDRES | F30: -140 | G30: K | H30: 46077 | I30: FACTURA AGUA | L30: 5.45 | M30: K | N30: 46094 | O30: PAGO CAJERO | R30: 100 | S30: K | T30: 46131 | U30: PAGO CAJERO | X30: 100 | Y30: K | Z30: 46150 | AA30: PAGO CAJERO | AD30: 50 | AE30: K | AF30: 46189 | AG30: PAGO CAJERO | AJ30: 100 | AK30: K | AL30: 46224 | AM30: PAGO CAJERO | AP30: 50 | AQ30: K | AR30: 46252 | AS30: PAGO CAJERO | AV30: 50 | AW30: K
B31: 46050 | C31: PAGO CAJERO | F31: 50 | G31: K | H31: 46080 | I31: PAGO CAJERO | L31: 50 | M31: K | N31: 46068 | O31: GASTOS TARJETA | R31: 566.11 | T31: 46134 | U31: BIZUM | X31: 18 | Y31: K | Z31: 46154 | AA31: BIZUM | AB31: ORLA | AD31: 15 | AE31: K | AF31: 46191 | AG31: TRASFERENCIA | AJ31: 50 | AK31: K | AL31: 46230 | AM31: GASTOS TARJETA | AP31: 25.13 | AR31: 46255 | AS31: GASTOS TARJETA | AV31: 168.92
H32: 46081 | I32: COMPRA | L32: 20 | M32: K | N32: 46097 | O32: PAGO CAJERO | R32: 50 | S32: K | T32: 46135 | U32: BIZUM | V32: LONDRES | X32: 100 | Y32: K | Z32: 46154 | AA32: BIZUM | AB32: PASTILLAS KALA | AD32: 54 | AE32: K | AF32: 46193 | AG32: PAGO CAJERO | AJ32: 50 | AK32: K | AL32: 46232 | AM32: PAGO CAJERO | AP32: 30 | AQ32: K | AR32: 46255 | AS32: PAGO CAJERO | AV32: 100 | AW32: K
H33: 46081 | I33: PAGO CAJERO | L33: 100 | M33: K | N33: 46099 | O33: PAGO CAJERO | R33: 250 | S33: K | T33: 46135 | U33: BIZUM | V33: LONDRES | X33: 100 | Y33: K | Z33: 46157 | AA33: PAGO CAJERO | AD33: 50 | AE33: K | AF33: 46196 | AG33: BIZUM | AH33: CAFES | AJ33: 3.4 | AK33: K | AL33: 46233 | AM33: GASTOS TARJETA | AP33: 54.99 | AR33: 46255 | AS33: GASTOS TARJETA | AV33: 35.65
H34: 46081 | I34: BIZUM | L34: 82 | M34: K | N34: 46104 | O34: MUGI | R34: 20 | S34: K | T34: 46136 | U34: PAGO CAJERO | X34: 50 | Y34: K | Z34: 46158 | AA34: GASTOS TARJETA | AD34: 446.76 | AF34: 46196 | AG34: BIZUM | AH34: CAMARA | AJ34: -155 | AK34: K | AL34: 46234 | AM34: GASTOS TARJETA | AP34: 31.9 | AR34: 46255 | AS34: BIZUM MILBY | AV34: -18.99 | AW34: K
N35: 46105 | O35: PAGO CAJERO | R35: 100 | S35: K | T35: 46137 | U35: OP.NET | X35: 10.8 | Y35: K | Z35: 46162 | AA35: PAGO CAJERO | AD35: 20 | AE35: K | AF35: 46197 | AG35: GASTOS TARJETA | AJ35: 788.39 | AR35: 46257 | AS35: PAGO CAJERO | AV35: 50 | AW35: K
N36: 46106 | O36: AMAIA | R36: 10 | S36: K | T36: 46138 | U36: GASTOS TARJETA | X36: 848.51 | Z36: 46163 | AA36: BIZUM COMPRA | AD36: 10 | AE36: K | AF36: 46203 | AG36: PAGO CAJERO | AJ36: 50 | AK36: K | AR36: 46259 | AS36: PAGO CAJERO | AV36: 50 | AW36: K
N37: 46110 | O37: PAGO CAJERO | R37: 50 | S37: K | T37: 46138 | U37: PAGO CAJERO | X37: 100 | Y37: K | Z37: 46164 | AA37: PAGO CAJERO | AD37: 70 | AE37: K | AR37: 46259 | AS37: PAGO CAJERO | AV37: 50 | AW37: K
N38: 46111 | O38: AMAIA | R38: 11.49 | S38: K | T38: 46138 | U38: BIZUM | V38: BOKATA | X38: 10 | Y38: K | Z38: 46166 | AA38: BIZUM COMPRA | AD38: 20 | AE38: K | AR38: 46261 | AS38: GASTOS TARJETA | AV38: 92.25
N39: 46111 | O39: GASTOS TARJETA | R39: 167.48 | T39: 46140 | U39: GASTOS TARJETA | X39: 28.99 | Z39: 46168 | AA39: BIZUM COMPRA | AD39: 14 | AE39: K | AR39: 46262 | AS39: GASTOS TARJETA | AV39: 17.01
Z40: 46171 | AA40: PAGO CAJERO | AD40: 50 | AE40: K | AR40: 46262 | AS40: PAGO CAJERO | AV40: 50 | AW40: K
Z41: 46172 | AA41: GASTOS TARJETA | AD41: 458.98 | AR41: 46263 | AS41: PAGO CAJERO | AV41: 20 | AW41: K
Z42: 46172 | AA42: PAGO CAJERO | AD42: 50 | AE42: K | AR42: 46264 | AS42: GASTOS TARJETA | AV42: 36.43
F53: =SUM(F22:F52) -> 628.72 | L53: =SUM(L22:L52) -> 1350.38 | R53: =SUM(R22:R52) -> 2188.18 | X53: =SUM(X22:X52) -> 1872.3 | AD53: =SUM(AD22:AD52) -> 2173.43 | AJ53: =SUM(AJ22:AJ52) -> 1503.24 | AP53: =SUM(AP22:AP52) -> 1948.73 | AV53: =SUM(AV22:AV52) -> 1406.57 | BB53: =SUM(BB22:BB52) -> 0 | BH53: =SUM(BH22:BH52) -> 0 | BN53: =SUM(BN22:BN52) -> 0 | BT53: =SUM(BT22:BT52) -> 0
F54: =F53 -> 628.72 | L54: =L53-L38 -> 1350.38 | R54: =R53-R33-R34 -> 1918.18
A56: N26 | B56: ENERO | H56: FEBRERO | N56: MARZO | T56: ABRIL | Z56: MAYO | AF56: JUNIO | AL56: JULIO | AR56: AGOSTO | AX56: SEPTIEMBRE | BD56: OCTUBRE | BJ56: NOVIEMBRE | BP56: DICIEMBRE
B57: DIA | C57: TIENDA | D57: CONCEPTO | E57: CATEGORIA | F57: CANTIDAD | G57: BANCO | H57: DIA | I57: TIENDA | J57: CONCEPTO | K57: CATEGORIA | L57: CANTIDAD | M57: BANCO | N57: DIA | O57: TIENDA | P57: CONCEPTO | Q57: CATEGORIA | R57: CANTIDAD | S57: BANCO | T57: DIA | U57: TIENDA | V57: CONCEPTO | W57: CATEGORIA | X57: CANTIDAD | Y57: BANCO | Z57: DIA | AA57: TIENDA | AB57: CONCEPTO | AC57: CATEGORIA | AD57: CANTIDAD | AE57: BANCO | AF57: DIA | AG57: TIENDA | AH57: CONCEPTO | AI57: CATEGORIA | AJ57: CANTIDAD | AK57: BANCO | AL57: DIA | AM57: TIENDA | AN57: CONCEPTO | AO57: CATEGORIA | AP57: CANTIDAD | AQ57: BANCO | AR57: DIA | AS57: TIENDA | AT57: CONCEPTO | AU57: CATEGORIA | AV57: CANTIDAD | AW57: BANCO | AX57: DIA | AY57: TIENDA | AZ57: CONCEPTO | BA57: CATEGORIA | BB57: CANTIDAD | BC57: BANCO | BD57: DIA | BE57: TIENDA | BF57: CONCEPTO | BG57: CATEGORIA | BH57: CANTIDAD | BI57: BANCO | BJ57: DIA | BK57: TIENDA | BL57: CONCEPTO | BM57: CATEGORIA | BN57: CANTIDAD | BO57: BANCO | BP57: DIA | BQ57: TIENDA | BR57: CONCEPTO | BS57: CATEGORIA | BT57: CANTIDAD | BU57: BANCO
...

Sheet ESCENARIOS
H1: 2025 | I1: 2026 | J1: 2027
H2: CON HIPOTECA SIN PRESTAMO CON LOCAL URKI BAJO CON ALQUILER VITORIA | K2: CON HIPOTECA CON PRESTAMO CON LOCAL URKI BAJO SIN ALQUILER VITORIA SIN TRASPORTE/SIN MATRICULAS | N2: SIN HIPOTECA SIN PRESTAMO CON LOCAL URKI BAJO SIN ALQUILER VITORIA SIN TRASPORTE/SIN MATRICULAS | Q2: CON HIPOTECA SIN PRESTAMO SIN LOCAL URKI BAJO CON ALQUILER VITORIA | T2: CON HIPOTECA SIN PRESTAMO SIN LOCAL URKI BAJO SIN ALQUILER VITORIA
A7: NOMINA JULIO | D7: 2300 | E7: MENSUAL | F7: =IF($E7="MENSUAL",$D7,IF($E7="TRIMESTRAL",$D7/3,IF($E7="SEMESTRAL",$D7/2,IF($E7="ANUAL",$D7/12,IF($E7="BIMENSUAL",$D7/2))))) -> 2300 | I7: =IF($E7="MENSUAL",$D7,IF($E7="TRIMESTRAL",$D7/3,IF($E7="SEMESTRAL",$D7/2,IF($E7="ANUAL",$D7/12,IF($E7="BIMENSUAL",$D7/2))))) -> 2300 | L7: =IF($E7="MENSUAL",$D7,IF($E7="TRIMESTRAL",$D7/3,IF($E7="SEMESTRAL",$D7/2,IF($E7="ANUAL",$D7/12,IF($E7="BIMENSUAL",$D7/2))))) -> 2300 | O7: =IF($E7="MENSUAL",$D7,IF($E7="TRIMESTRAL",$D7/3,IF($E7="SEMESTRAL",$D7/2,IF($E7="ANUAL",$D7/12,IF($E7="BIMENSUAL",$D7/2))))) -> 2300 | R7: =IF($E7="MENSUAL",$D7,IF($E7="TRIMESTRAL",$D7/3,IF($E7="SEMESTRAL",$D7/2,IF($E7="ANUAL",$D7/12,IF($E7="BIMENSUAL",$D7/2))))) -> 2300 | U7: =IF($E7="MENSUAL",$D7,IF($E7="TRIMESTRAL",$D7/3,IF($E7="SEMESTRAL",$D7/2,IF($E7="ANUAL",$D7/12,IF($E7="BIMENSUAL",$D7/2))))) -> 2300
A8: PAGA VERANO | D8: 1900 | E8: ANUAL | F8: =IF($E8="MENSUAL",$D8,IF($E8="TRIMESTRAL",$D8/3,IF($E8="SEMESTRAL",$D8/2,IF($E8="ANUAL",$D8/12,IF($E8="BIMENSUAL",$D8/2))))) -> 158.33333 | I8: =IF($E8="MENSUAL",$D8,IF($E8="TRIMESTRAL",$D8/3,IF($E8="SEMESTRAL",$D8/2,IF($E8="ANUAL",$D8/12,IF($E8="BIMENSUAL",$D8/2))))) -> 158.33333 | L8: =IF($E8="MENSUAL",$D8,IF($E8="TRIMESTRAL",$D8/3,IF($E8="SEMESTRAL",$D8/2,IF($E8="ANUAL",$D8/12,IF($E8="BIMENSUAL",$D8/2))))) -> 158.33333 | O8: =IF($E8="MENSUAL",$D8,IF($E8="TRIMESTRAL",$D8/3,IF($E8="SEMESTRAL",$D8/2,IF($E8="ANUAL",$D8/12,IF($E8="BIMENSUAL",$D8/2))))) -> 158.33333 | R8: =IF($E8="MENSUAL",$D8,IF($E8="TRIMESTRAL",$D8/3,IF($E8="SEMESTRAL",$D8/2,IF($E8="ANUAL",$D8/12,IF($E8="BIMENSUAL",$D8/2))))) -> 158.33333 | U8: =IF($E8="MENSUAL",$D8,IF($E8="TRIMESTRAL",$D8/3,IF($E8="SEMESTRAL",$D8/2,IF($E8="ANUAL",$D8/12,IF($E8="BIMENSUAL",$D8/2))))) -> 158.33333
A9: PAGA NAVIDAD | D9: 1900 | E9: ANUAL | F9: =IF($E9="MENSUAL",$D9,IF($E9="TRIMESTRAL",$D9/3,IF($E9="SEMESTRAL",$D9/2,IF($E9="ANUAL",$D9/12,IF($E9="BIMENSUAL",$D9/2))))) -> 158.33333 | I9: =IF($E9="MENSUAL",$D9,IF($E9="TRIMESTRAL",$D9/3,IF($E9="SEMESTRAL",$D9/2,IF($E9="ANUAL",$D9/12,IF($E9="BIMENSUAL",$D9/2))))) -> 158.33333 | L9: =IF($E9="MENSUAL",$D9,IF($E9="TRIMESTRAL",$D9/3,IF($E9="SEMESTRAL",$D9/2,IF($E9="ANUAL",$D9/12,IF($E9="BIMENSUAL",$D9/2))))) -> 158.33333 | O9: =IF($E9="MENSUAL",$D9,IF($E9="TRIMESTRAL",$D9/3,IF($E9="SEMESTRAL",$D9/2,IF($E9="ANUAL",$D9/12,IF($E9="BIMENSUAL",$D9/2))))) -> 158.33333 | R9: =IF($E9="MENSUAL",$D9,IF($E9="TRIMESTRAL",$D9/3,IF($E9="SEMESTRAL",$D9/2,IF($E9="ANUAL",$D9/12,IF($E9="BIMENSUAL",$D9/2))))) -> 158.33333 | U9: =IF($E9="MENSUAL",$D9,IF($E9="TRIMESTRAL",$D9/3,IF($E9="SEMESTRAL",$D9/2,IF($E9="ANUAL",$D9/12,IF($E9="BIMENSUAL",$D9/2))))) -> 158.33333
A10: NOMINA YOLI | D10: 2350 | E10: MENSUAL | F10: =IF($E10="MENSUAL",$D10,IF($E10="TRIMESTRAL",$D10/3,IF($E10="SEMESTRAL",$D10/2,IF($E10="ANUAL",$D10/12,IF($E10="BIMENSUAL",$D10/2))))) -> 2350 | I10: =IF($E10="MENSUAL",$D10,IF($E10="TRIMESTRAL",$D10/3,IF($E10="SEMESTRAL",$D10/2,IF($E10="ANUAL",$D10/12,IF($E10="BIMENSUAL",$D10/2))))) -> 2350 | L10: =IF($E10="MENSUAL",$D10,IF($E10="TRIMESTRAL",$D10/3,IF($E10="SEMESTRAL",$D10/2,IF($E10="ANUAL",$D10/12,IF($E10="BIMENSUAL",$D10/2))))) -> 2350 | O10: =IF($E10="MENSUAL",$D10,IF($E10="TRIMESTRAL",$D10/3,IF($E10="SEMESTRAL",$D10/2,IF($E10="ANUAL",$D10/12,IF($E10="BIMENSUAL",$D10/2))))) -> 2350 | R10: =IF($E10="MENSUAL",$D10,IF($E10="TRIMESTRAL",$D10/3,IF($E10="SEMESTRAL",$D10/2,IF($E10="ANUAL",$D10/12,IF($E10="BIMENSUAL",$D10/2))))) -> 2350 | U10: =IF($E10="MENSUAL",$D10,IF($E10="TRIMESTRAL",$D10/3,IF($E10="SEMESTRAL",$D10/2,IF($E10="ANUAL",$D10/12,IF($E10="BIMENSUAL",$D10/2))))) -> 2350
A11: HACIENDA | D11: 4000 | E11: ANUAL | F11: =IF($E11="MENSUAL",$D11,IF($E11="TRIMESTRAL",$D11/3,IF($E11="SEMESTRAL",$D11/2,IF($E11="ANUAL",$D11/12,IF($E11="BIMENSUAL",$D11/2))))) -> 333.33333 | I11: =IF($E11="MENSUAL",$D11,IF($E11="TRIMESTRAL",$D11/3,IF($E11="SEMESTRAL",$D11/2,IF($E11="ANUAL",$D11/12,IF($E11="BIMENSUAL",$D11/2))))) -> 333.33333 | L11: =IF($E11="MENSUAL",$D11,IF($E11="TRIMESTRAL",$D11/3,IF($E11="SEMESTRAL",$D11/2,IF($E11="ANUAL",$D11/12,IF($E11="BIMENSUAL",$D11/2))))) -> 333.33333 | O11: =IF($E11="MENSUAL",$D11,IF($E11="TRIMESTRAL",$D11/3,IF($E11="SEMESTRAL",$D11/2,IF($E11="ANUAL",$D11/12,IF($E11="BIMENSUAL",$D11/2))))) -> 333.33333 | R11: =IF($E11="MENSUAL",$D11,IF($E11="TRIMESTRAL",$D11/3,IF($E11="SEMESTRAL",$D11/2,IF($E11="ANUAL",$D11/12,IF($E11="BIMENSUAL",$D11/2))))) -> 333.33333 | U11: =IF($E11="MENSUAL",$D11,IF($E11="TRIMESTRAL",$D11/3,IF($E11="SEMESTRAL",$D11/2,IF($E11="ANUAL",$D11/12,IF($E11="BIMENSUAL",$D11/2))))) -> 333.33333
A12: GESTION COMUNIDAD | D12: 0 | E12: ANUAL | F12: =IF($E12="MENSUAL",$D12,IF($E12="TRIMESTRAL",$D12/3,IF($E12="SEMESTRAL",$D12/2,IF($E12="ANUAL",$D12/12,IF($E12="BIMENSUAL",$D12/2))))) -> 0 | I12: =IF($E12="MENSUAL",$D12,IF($E12="TRIMESTRAL",$D12/3,IF($E12="SEMESTRAL",$D12/2,IF($E12="ANUAL",$D12/12,IF($E12="BIMENSUAL",$D12/2))))) -> 0 | L12: =IF($E12="MENSUAL",$D12,IF($E12="TRIMESTRAL",$D12/3,IF($E12="SEMESTRAL",$D12/2,IF($E12="ANUAL",$D12/12,IF($E12="BIMENSUAL",$D12/2))))) -> 0 | O12: =IF($E12="MENSUAL",$D12,IF($E12="TRIMESTRAL",$D12/3,IF($E12="SEMESTRAL",$D12/2,IF($E12="ANUAL",$D12/12,IF($E12="BIMENSUAL",$D12/2))))) -> 0 | R12: =IF($E12="MENSUAL",$D12,IF($E12="TRIMESTRAL",$D12/3,IF($E12="SEMESTRAL",$D12/2,IF($E12="ANUAL",$D12/12,IF($E12="BIMENSUAL",$D12/2))))) -> 0 | U12: =IF($E12="MENSUAL",$D12,IF($E12="TRIMESTRAL",$D12/3,IF($E12="SEMESTRAL",$D12/2,IF($E12="ANUAL",$D12/12,IF($E12="BIMENSUAL",$D12/2))))) -> 0
F13: =SUM(F7:F12) -> 5300 | I13: =SUM(I7:I12) -> 5300 | J13: =I13*12 -> 63600 | L13: =SUM(L7:L12) -> 5300 | M13: =L13*12 -> 63600 | O13: =SUM(O7:O12) -> 5300 | P13: =O13*12 -> 63600 | R13: =SUM(R7:R12) -> 5300 | S13: =R13*12 -> 63600 | U13: =SUM(U7:U12) -> 5300 | V13: =U13*12 -> 63600
C15: GASTOS | I15: =SUMIF($C$41:$C$126,$C15,$I$41:$I$126) -> 1400 | J15: =-(F15-I15) -> 1400 | L15: =SUMIF($C$41:$C$126,$C15,$L$41:$L$126) -> 1400 | M15: =-(I15-L15) -> 0 | O15: =SUMIF($C$41:$C$126,$C15,$O$41:$O$126) -> 1400 | P15: =-(I15-O15) -> 0 | R15: =SUMIF($C$41:$C$126,$C15,$R$41:$R$126) -> 1400 | S15: =-(I15-R15) -> 0 | U15: =SUMIF($C$41:$C$126,$C15,$U$41:$U$126) -> 1400 | V15: =-(I15-U15) -> 0
C16: HIPOTECA | I16: =SUMIF($C$41:$C$126,$C16,$I$41:$I$126) -> 810 | J16: =-(F16-I16) -> 810 | L16: =SUMIF($C$41:$C$126,$C16,$L$41:$L$126) -> 810 | M16: =-(I16-L16) -> 0 | O16: =SUMIF($C$41:$C$126,$C16,$O$41:$O$126) -> 0 | P16: =-(I16-O16) -> -810 | R16: =SUMIF($C$41:$C$126,$C16,$R$41:$R$126) -> 810 | S16: =-(I16-R16) -> 0 | U16: =SUMIF($C$41:$C$126,$C16,$U$41:$U$126) -> 810 | V16: =-(I16-U16) -> 0
C17: AHORRO | I17: =SUMIF($C$41:$C$126,$C17,$I$41:$I$126) -> 0 | J17: =-(F17-I17) -> 0 | L17: =SUMIF($C$41:$C$126,$C17,$L$41:$L$126) -> 0 | M17: =-(I17-L17) -> 0 | O17: =SUMIF($C$41:$C$126,$C17,$O$41:$O$126) -> 0 | P17: =-(I17-O17) -> 0 | R17: =SUMIF($C$41:$C$126,$C17,$R$41:$R$126) -> 0 | S17: =-(I17-R17) -> 0 | U17: =SUMIF($C$41:$C$126,$C17,$U$41:$U$126) -> 0 | V17: =-(I17-U17) -> 0
C18: PRESTAMO | I18: =SUMIF($C$41:$C$126,$C18,$I$41:$I$126) -> 500 | J18: =-(F18-I18) -> 500 | L18: =SUMIF($C$41:$C$126,$C18,$L$41:$L$126) -> 500 | M18: =-(I18-L18) -> 0 | O18: =SUMIF($C$41:$C$126,$C18,$O$41:$O$126) -> 0 | P18: =-(I18-O18) -> -500 | R18: =SUMIF($C$41:$C$126,$C18,$R$41:$R$126) -> 0 | S18: =-(I18-R18) -> -500 | U18: =SUMIF($C$41:$C$126,$C18,$U$41:$U$126) -> 0 | V18: =-(I18-U18) -> -500
C19: CASA | I19: =SUMIF($C$41:$C$126,$C19,$I$41:$I$126) -> 391.58 | J19: =-(F19-I19) -> 391.58 | L19: =SUMIF($C$41:$C$126,$C19,$L$41:$L$126) -> 391.58 | M19: =-(I19-L19) -> 0 | O19: =SUMIF($C$41:$C$126,$C19,$O$41:$O$126) -> 391.58 | P19: =-(I19-O19) -> 0 | R19: =SUMIF($C$41:$C$126,$C19,$R$41:$R$126) -> 391.58 | S19: =-(I19-R19) -> 0 | U19: =SUMIF($C$41:$C$126,$C19,$U$41:$U$126) -> 391.58 | V19: =-(I19-U19) -> 0
C20: ESTUDIOS | I20: =SUMIF($C$41:$C$126,$C20,$I$41:$I$126) -> 258.33333 | J20: =-(F20-I20) -> 258.33333 | L20: =SUMIF($C$41:$C$126,$C20,$L$41:$L$126) -> 258.33333 | M20: =-(I20-L20) -> 0 | O20: =SUMIF($C$41:$C$126,$C20,$O$41:$O$126) -> 0 | P20: =-(I20-O20) -> -258.33333 | R20: =SUMIF($C$41:$C$126,$C20,$R$41:$R$126) -> 258.33333 | S20: =-(I20-R20) -> 0 | U20: =SUMIF($C$41:$C$126,$C20,$U$41:$U$126) -> 258.33333 | V20: =-(I20-U20) -> 0
C21: SINDICATO | I21: =SUMIF($C$41:$C$126,$C21,$I$41:$I$126) -> 20.58 | J21: =-(F21-I21) -> 20.58 | L21: =SUMIF($C$41:$C$126,$C21,$L$41:$L$126) -> 20.58 | M21: =-(I21-L21) -> 0 | O21: =SUMIF($C$41:$C$126,$C21,$O$41:$O$126) -> 20.58 | P21: =-(I21-O21) -> 0 | R21: =SUMIF($C$41:$C$126,$C21,$R$41:$R$126) -> 20.58 | S21: =-(I21-R21) -> 0 | U21: =SUMIF($C$41:$C$126,$C21,$U$41:$U$126) -> 20.58 | V21: =-(I21-U21) -> 0
C22: COCHE | I22: =SUMIF($C$41:$C$126,$C22,$I$41:$I$126) -> 149.16667 | J22: =-(F22-I22) -> 149.16667 | L22: =SUMIF($C$41:$C$126,$C22,$L$41:$L$126) -> 149.16667 | M22: =-(I22-L22) -> 0 | O22: =SUMIF($C$41:$C$126,$C22,$O$41:$O$126) -> 149.16667 | P22: =-(I22-O22) -> 0 | R22: =SUMIF($C$41:$C$126,$C22,$R$41:$R$126) -> 149.16667 | S22: =-(I22-R22) -> 0 | U22: =SUMIF($C$41:$C$126,$C22,$U$41:$U$126) -> 149.16667 | V22: =-(I22-U22) -> 0
C23: TRANSPORTE | I23: =SUMIF($C$41:$C$126,$C23,$I$41:$I$126) -> 250 | J23: =-(F23-I23) -> 250 | L23: =SUMIF($C$41:$C$126,$C23,$L$41:$L$126) -> 250 | M23: =-(I23-L23) -> 0 | O23: =SUMIF($C$41:$C$126,$C23,$O$41:$O$126) -> 50 | P23: =-(I23-O23) -> -200 | R23: =SUMIF($C$41:$C$126,$C23,$R$41:$R$126) -> 250 | S23: =-(I23-R23) -> 0 | U23: =SUMIF($C$41:$C$126,$C23,$U$41:$U$126) -> 250 | V23: =-(I23-U23) -> 0
C24: OCIO | I24: =SUMIF($C$41:$C$126,$C24,$I$41:$I$126) -> 113.41667 | J24: =-(F24-I24) -> 113.41667 | L24: =SUMIF($C$41:$C$126,$C24,$L$41:$L$126) -> 113.41667 | M24: =-(I24-L24) -> 0 | O24: =SUMIF($C$41:$C$126,$C24,$O$41:$O$126) -> 98.75 | P24: =-(I24-O24) -> -14.666667 | R24: =SUMIF($C$41:$C$126,$C24,$R$41:$R$126) -> 113.41667 | S24: =-(I24-R24) -> 0 | U24: =SUMIF($C$41:$C$126,$C24,$U$41:$U$126) -> 113.41667 | V24: =-(I24-U24) -> 0
C25: LOCALES | I25: =SUMIF($C$41:$C$126,$C25,$I$41:$I$126) -> 58.083333 | J25: =-(F25-I25) -> 58.083333 | L25: =SUMIF($C$41:$C$126,$C25,$L$41:$L$126) -> 58.083333 | M25: =-(I25-L25) -> 0 | O25: =SUMIF($C$41:$C$126,$C25,$O$41:$O$126) -> 58.083333 | P25: =-(I25-O25) -> 0 | R25: =SUMIF($C$41:$C$126,$C25,$R$41:$R$126) -> 0 | S25: =-(I25-R25) -> -58.083333 | U25: =SUMIF($C$41:$C$126,$C25,$U$41:$U$126) -> 0 | V25: =-(I25-U25) -> -58.083333
C26: INVERSION | I26: =SUMIF($C$41:$C$126,$C26,$I$41:$I$126) -> 64 | J26: =-(F26-I26) -> 64 | L26: =SUMIF($C$41:$C$126,$C26,$L$41:$L$126) -> 64 | M26: =-(I26-L26) -> 0 | O26: =SUMIF($C$41:$C$126,$C26,$O$41:$O$126) -> 64 | P26: =-(I26-O26) -> 0 | R26: =SUMIF($C$41:$C$126,$C26,$R$41:$R$126) -> 64 | S26: =-(I26-R26) -> 0 | U26: =SUMIF($C$41:$C$126,$C26,$U$41:$U$126) -> 64 | V26: =-(I26-U26) -> 0
... C34: SALUD | I34: =SUMIF($C$41:$C$126,$C34,$I$41:$I$126) -> 83.333333 | J34: =-(F34-I34) -> 83.333333 | L34: =SUMIF($C$41:$C$126,$C34,$L$41:$L$126) -> 83.333333 | M34: =-(I34-L34) -> 0 | O34: =SUMIF($C$41:$C$126,$C34,$O$41:$O$126) -> 83.333333 | P34: =-(I34-O34) -> 0 | R34: =SUMIF($C$41:$C$126,$C34,$R$41:$R$126) -> 83.333333 | S34: =-(I34-R34) -> 0 | U34: =SUMIF($C$41:$C$126,$C34,$U$41:$U$126) -> 83.333333 | V34: =-(I34-U34) -> 0
I35: =SUBTOTAL(9,I15:I34) -> 4973.4933 | J35: =I35*12 -> 59681.92 | L35: =SUBTOTAL(9,L15:L34) -> 4973.4933 | M35: =L35*12 -> 59681.92 | O35: =SUBTOTAL(9,O15:O34) -> 2915.4933 | P35: =O35*12 -> 34985.92 | R35: =SUBTOTAL(9,R15:R34) -> 4415.41 | S35: =R35*12 -> 52984.92 | U35: =SUBTOTAL(9,U15:U34) -> 4140.41 | V35: =U35*12 -> 49684.92
A37: AHORRO | I37: =I13-I35 -> 326.50667 | L37: =L13-L35 -> 326.50667 | O37: =O13-O35 -> 2384.5067 | R37: =R13-R35 -> 884.59 | U37: =U13-U35 -> 1159.59
A40: CONCEPTO | B40: BANCO | C40: CATEGORIA | D40: COSTE | E40: TIPO | F40: AL MES | H40: PRESCINDIBLE | I40: AL MES | K40: PRESCINDIBLE | L40: AL MES | N40: PRESCINDIBLE | O40: AL MES | Q40: PRESCINDIBLE | R40: AL MES | T40: PRESCINDIBLE | U40: AL MES
A41: HIPOTECA | B41: SANTANDER | C41: HIPOTECA | D41: 810 | E41: MENSUAL | F41: =IF($E41="MENSUAL",$D41,IF($E41="TRIMESTRAL",$D41/3,IF($E41="SEMESTRAL",$D41/2,IF($E41="ANUAL",$D41/12,IF($E41="BIMENSUAL",$D41/2))))) -> 810 | H41: NO | I41: =IF($H41="NO",IF($E41="MENSUAL",$D41,IF($E41="TRIMESTRAL",$D41/3,IF($E41="SEMESTRAL",$D41/2,IF($E41="ANUAL",$D41/12,IF($E41="BIMENSUAL",$D41/2))))),0) -> 810 | K41: NO | L41: =IF($H41="NO",IF($E41="MENSUAL",$D41,IF($E41="TRIMESTRAL",$D41/3,IF($E41="SEMESTRAL",$D41/2,IF($E41="ANUAL",$D41/12,IF($E41="BIMENSUAL",$D41/2))))),0) -> 810 | N41: SI | O41: =IF($N41="NO",IF($E41="MENSUAL",$D41,IF($E41="TRIMESTRAL",$D41/3,IF($E41="SEMESTRAL",$D41/2,IF($E41="ANUAL",$D41/12,IF($E41="BIMENSUAL",$D41/2))))),0) -> 0 | Q41: NO | R41: =IF($Q41="NO",IF($E41="MENSUAL",$D41,IF($E41="TRIMESTRAL",$D41/3,IF($E41="SEMESTRAL",$D41/2,IF($E41="ANUAL",$D41/12,IF($E41="BIMENSUAL",$D41/2))))),0) -> 810 | T41: NO | U41: =IF($T41="NO",IF($E41="MENSUAL",$D41,IF($E41="TRIMESTRAL",$D41/3,IF($E41="SEMESTRAL",$D41/2,IF($E41="ANUAL",$D41/12,IF($E41="BIMENSUAL",$D41/2))))),0) -> 810
A42: AHORRO | B42: SANTANDER | C42: AHORRO | D42: 0 | E42: ANUAL | F42: =IF($E42="MENSUAL",$D42,IF($E42="TRIMESTRAL",$D42/3,IF($E42="SEMESTRAL",$D42/2,IF($E42="ANUAL",$D42/12,IF($E42="BIMENSUAL",$D42/2))))) -> 0 | H42: NO | I42: =IF($H42="NO",IF($E42="MENSUAL",$D42,IF($E42="TRIMESTRAL",$D42/3,IF($E42="SEMESTRAL",$D42/2,IF($E42="ANUAL",$D42/12,IF($E42="BIMENSUAL",$D42/2))))),0) -> 0 | K42: NO | L42: =IF($H42="NO",IF($E42="MENSUAL",$D42,IF($E42="TRIMESTRAL",$D42/3,IF($E42="SEMESTRAL",$D42/2,IF($E42="ANUAL",$D42/12,IF($E42="BIMENSUAL",$D42/2))))),0) -> 0 | N42: NO | O42: =IF($N42="NO",IF($E42="MENSUAL",$D42,IF($E42="TRIMESTRAL",$D42/3,IF($E42="SEMESTRAL",$D42/2,IF($E42="ANUAL",$D42/12,IF($E42="BIMENSUAL",$D42/2))))),0) -> 0 | Q42: NO | R42: =IF($Q42="NO",IF($E42="MENSUAL",$D42,IF($E42="TRIMESTRAL",$D42/3,IF($E42="SEMESTRAL",$D42/2,IF($E42="ANUAL",$D42/12,IF($E42="BIMENSUAL",$D42/2))))),0) -> 0 | T42: NO | U42: =IF($T42="NO",IF($E42="MENSUAL",$D42,IF($E42="TRIMESTRAL",$D42/3,IF($E42="SEMESTRAL",$D42/2,IF($E42="ANUAL",$D42/12,IF($E42="BIMENSUAL",$D42/2))))),0) -> 0
A43: COMUNIDAD | B43: SANTANDER | C43: CASA | D43: 43.83 | E43: MENSUAL | F43: =IF($E43="MENSUAL",$D43,IF($E43="TRIMESTRAL",$D43/3,IF($E43="SEMESTRAL",$D43/2,IF($E43="ANUAL",$D43/12,IF($E43="BIMENSUAL",$D43/2))))) -> 43.83 | H43: NO | I43: =IF($H43="NO",IF($E43="MENSUAL",$D43,IF($E43="TRIMESTRAL",$D43/3,IF($E43="SEMESTRAL",$D43/2,IF($E43="ANUAL",$D43/12,IF($E43="BIMENSUAL",$D43/2))))),0) -> 43.83 | K43: NO | L43: =IF($H43="NO",IF($E43="MENSUAL",$D43,IF($E43="TRIMESTRAL",$D43/3,IF($E43="SEMESTRAL",$D43/2,IF($E43="ANUAL",$D43/12,IF($E43="BIMENSUAL",$D43/2))))),0) -> 43.83 | N43: NO | O43: =IF($N43="NO",IF($E43="MENSUAL",$D43,IF($E43="TRIMESTRAL",$D43/3,IF($E43="SEMESTRAL",$D43/2,IF($E43="ANUAL",$D43/12,IF($E43="BIMENSUAL",$D43/2))))),0) -> 43.83 | Q43: NO | R43: =IF($Q43="NO",IF($E43="MENSUAL",$D43,IF($E43="TRIMESTRAL",$D43/3,IF($E43="SEMESTRAL",$D43/2,IF($E43="ANUAL",$D43/12,IF($E43="BIMENSUAL",$D43/2))))),0) -> 43.83 | T43: NO | U43: =IF($T43="NO",IF($E43="MENSUAL",$D43,IF($E43="TRIMESTRAL",$D43/3,IF($E43="SEMESTRAL",$D43/2,IF($E43="ANUAL",$D43/12,IF($E43="BIMENSUAL",$D43/2))))),0) -> 43.83
A44: SOCIEDAD OTARRA (KUTXA) | B44: SANTANDER | C44: OCIO | D44: 30 | E44: MENSUAL | F44: =IF($E44="MENSUAL",$D44,IF($E44="TRIMESTRAL",$D44/3,IF($E44="SEMESTRAL",$D44/2,IF($E44="ANUAL",$D44/12,IF($E44="BIMENSUAL",$D44/2))))) -> 30 | G44: X | H44: NO | I44: =IF($H44="NO",IF($E44="MENSUAL",$D44,IF($E44="TRIMESTRAL",$D44/3,IF($E44="SEMESTRAL",$D44/2,IF($E44="ANUAL",$D44/12,IF($E44="BIMENSUAL",$D44/2))))),0) -> 30 | K44: NO | L44: =IF($H44="NO",IF($E44="MENSUAL",$D44,IF($E44="TRIMESTRAL",$D44/3,IF($E44="SEMESTRAL",$D44/2,IF($E44="ANUAL",$D44/12,IF($E44="BIMENSUAL",$D44/2))))),0) -> 30 | N44: NO | O44: =IF($N44="NO",IF($E44="MENSUAL",$D44,IF($E44="TRIMESTRAL",$D44/3,IF($E44="SEMESTRAL",$D44/2,IF($E44="ANUAL",$D44/12,IF($E44="BIMENSUAL",$D44/2))))),0) -> 30 | Q44: NO | R44: =IF($Q44="NO",IF($E44="MENSUAL",$D44,IF($E44="TRIMESTRAL",$D44/3,IF($E44="SEMESTRAL",$D44/2,IF($E44="ANUAL",$D44/12,IF($E44="BIMENSUAL",$D44/2))))),0) -> 30 | T44: NO | U44: =IF($T44="NO",IF($E44="MENSUAL",$D44,IF($E44="TRIMESTRAL",$D44/3,IF($E44="SEMESTRAL",$D44/2,IF($E44="ANUAL",$D44/12,IF($E44="BIMENSUAL",$D44/2))))),0) -> 30
A45: NETFLIX+HBO | B45: SANTANDER | C45: OCIO | D45: 7.5 | E45: MENSUAL | F45: =IF($E45="MENSUAL",$D45,IF($E45="TRIMESTRAL",$D45/3,IF($E45="SEMESTRAL",$D45/2,IF($E45="ANUAL",$D45/12,IF($E45="BIMENSUAL",$D45/2))))) -> 7.5 | H45: NO | I45: =IF($H45="NO",IF($E45="MENSUAL",$D45,IF($E45="TRIMESTRAL",$D45/3,IF($E45="SEMESTRAL",$D45/2,IF($E45="ANUAL",$D45/12,IF($E45="BIMENSUAL",$D45/2))))),0) -> 7.5 | K45: NO | L45: =IF($H45="NO",IF($E45="MENSUAL",$D45,IF($E45="TRIMESTRAL",$D45/3,IF($E45="SEMESTRAL",$D45/2,IF($E45="ANUAL",$D45/12,IF($E45="BIMENSUAL",$D45/2))))),0) -> 7.5 | N45: NO | O45: =IF($N45="NO",IF($E45="MENSUAL",$D45,IF($E45="TRIMESTRAL",$D45/3,IF($E45="SEMESTRAL",$D45/2,IF($E45="ANUAL",$D45/12,IF($E45="BIMENSUAL",$D45/2))))),0) -> 7.5 | Q45: NO | R45: =IF($Q45="NO",IF($E45="MENSUAL",$D45,IF($E45="TRIMESTRAL",$D45/3,IF($E45="SEMESTRAL",$D45/2,IF($E45="ANUAL",$D45/12,IF($E45="BIMENSUAL",$D45/2))))),0) -> 7.5 | T45: NO | U45: =IF($T45="NO",IF($E45="MENSUAL",$D45,IF($E45="TRIMESTRAL",$D45/3,IF($E45="SEMESTRAL",$D45/2,IF($E45="ANUAL",$D45/12,IF($E45="BIMENSUAL",$D45/2))))),0) -> 7.5
A46: LOCAL AMAIA/OLATZ | B46: SANTANDER | C46: OCIO | D46: 30 | E46: MENSUAL | F46: =IF($E46="MENSUAL",$D46,IF($E46="TRIMESTRAL",$D46/3,IF($E46="SEMESTRAL",$D46/2,IF($E46="ANUAL",$D46/12,IF($E46="BIMENSUAL",$D46/2))))) -> 30 | H46: SI | I46: =IF($H46="NO",IF($E46="MENSUAL",$D46,IF($E46="TRIMESTRAL",$D46/3,IF($E46="SEMESTRAL",$D46/2,IF($E46="ANUAL",$D46/12,IF($E46="BIMENSUAL",$D46/2))))),0) -> 0 | K46: SI | L46: =IF($H46="NO",IF($E46="MENSUAL",$D46,IF($E46="TRIMESTRAL",$D46/3,IF($E46="SEMESTRAL",$D46/2,IF($E46="ANUAL",$D46/12,IF($E46="BIMENSUAL",$D46/2))))),0) -> 0 | N46: SI | O46: =IF($N46="NO",IF($E46="MENSUAL",$D46,IF($E46="TRIMESTRAL",$D46/3,IF($E46="SEMESTRAL",$D46/2,IF($E46="ANUAL",$D46/12,IF($E46="BIMENSUAL",$D46/2))))),0) -> 0 | Q46: SI | R46: =IF($Q46="NO",IF($E46="MENSUAL",$D46,IF($E46="TRIMESTRAL",$D46/3,IF($E46="SEMESTRAL",$D46/2,IF($E46="ANUAL",$D46/12,IF($E46="BIMENSUAL",$D46/2))))),0) -> 0 | T46: SI | U46: =IF($T46="NO",IF($E46="MENSUAL",$D46,IF($E46="TRIMESTRAL",$D46/3,IF($E46="SEMESTRAL",$D46/2,IF($E46="ANUAL",$D46/12,IF($E46="BIMENSUAL",$D46/2))))),0) -> 0
A47: SEGURO VIDA 1 (SANTANDER SEG) | B47: SANTANDER | C47: CASA | D47: 217 | E47: ANUAL | F47: =IF($E47="MENSUAL",$D47,IF($E47="TRIMESTRAL",$D47/3,IF($E47="SEMESTRAL",$D47/2,IF($E47="ANUAL",$D47/12,IF($E47="BIMENSUAL",$D47/2))))) -> 18.083333 | H47: NO | I47: =IF($H47="NO",IF($E47="MENSUAL",$D47,IF($E47="TRIMESTRAL",$D47/3,IF($E47="SEMESTRAL",$D47/2,IF($E47="ANUAL",$D47/12,IF($E47="BIMENSUAL",$D47/2))))),0) -> 18.083333 | K47: NO | L47: =IF($H47="NO",IF($E47="MENSUAL",$D47,IF($E47="TRIMESTRAL",$D47/3,IF($E47="SEMESTRAL",$D47/2,IF($E47="ANUAL",$D47/12,IF($E47="BIMENSUAL",$D47/2))))),0) -> 18.083333 | N47: NO | O47: =IF($N47="NO",IF($E47="MENSUAL",$D47,IF($E47="TRIMESTRAL",$D47/3,IF($E47="SEMESTRAL",$D47/2,IF($E47="ANUAL",$D47/12,IF($E47="BIMENSUAL",$D47/2))))),0) -> 18.083333 | Q47: NO | R47: =IF($Q47="NO",IF($E47="MENSUAL",$D47,IF($E47="TRIMESTRAL",$D47/3,IF($E47="SEMESTRAL",$D47/2,IF($E47="ANUAL",$D47/12,IF($E47="BIMENSUAL",$D47/2))))),0) -> 18.083333 | T47: NO | U47: =IF($T47="NO",IF($E47="MENSUAL",$D47,IF($E47="TRIMESTRAL",$D47/3,IF($E47="SEMESTRAL",$D47/2,IF($E47="ANUAL",$D47/12,IF($E47="BIMENSUAL",$D47/2))))),0) -> 18.083333
A48: SEGURO VIDA 2 (SANTANDER SEG) | B48: SANTANDER | C48: CASA | D48: 200 | E48: ANUAL | F48: =IF($E48="MENSUAL",$D48,IF($E48="TRIMESTRAL",$D48/3,IF($E48="SEMESTRAL",$D48/2,IF($E48="ANUAL",$D48/12,IF($E48="BIMENSUAL",$D48/2))))) -> 16.666667 | H48: NO | I48: =IF($H48="NO",IF($E48="MENSUAL",$D48,IF($E48="TRIMESTRAL",$D48/3,IF($E48="SEMESTRAL",$D48/2,IF($E48="ANUAL",$D48/12,IF($E48="BIMENSUAL",$D48/2))))),0) -> 16.666667 | K48: NO | L48: =IF($H48="NO",IF($E48="MENSUAL",$D48,IF($E48="TRIMESTRAL",$D48/3,IF($E48="SEMESTRAL",$D48/2,IF($E48="ANUAL",$D48/12,IF($E48="BIMENSUAL",$D48/2))))),0) -> 16.666667 | N48: NO | O48: =IF($N48="NO",IF($E48="MENSUAL",$D48,IF($E48="TRIMESTRAL",$D48/3,IF($E48="SEMESTRAL",$D48/2,IF($E48="ANUAL",$D48/12,IF($E48="BIMENSUAL",$D48/2))))),0) -> 16.666667 | Q48: NO | R48: =IF($Q48="NO",IF($E48="MENSUAL",$D48,IF($E48="TRIMESTRAL",$D48/3,IF($E48="SEMESTRAL",$D48/2,IF($E48="ANUAL",$D48/12,IF($E48="BIMENSUAL",$D48/2))))),0) -> 16.666667 | T48: NO | U48: =IF($T48="NO",IF($E48="MENSUAL",$D48,IF($E48="TRIMESTRAL",$D48/3,IF($E48="SEMESTRAL",$D48/2,IF($E48="ANUAL",$D48/12,IF($E48="BIMENSUAL",$D48/2))))),0) -> 16.666667
A49: CONTRIBUCION.IBI URBANA (Eibarko udala) | B49: SANTANDER | C49: CASA | D49: 310 | E49: ANUAL | F49: =IF($E49="MENSUAL",$D49,IF($E49="TRIMESTRAL",$D49/3,IF($E49="SEMESTRAL",$D49/2,IF($E49="ANUAL",$D49/12,IF($E49="BIMENSUAL",$D49/2))))) -> 25.833333 | H49: NO | I49: =IF($H49="NO",IF($E49="MENSUAL",$D49,IF($E49="TRIMESTRAL",$D49/3,IF($E49="SEMESTRAL",$D49/2,IF($E49="ANUAL",$D49/12,IF($E49="BIMENSUAL",$D49/2))))),0) -> 25.833333 | K49: NO | L49: =IF($H49="NO",IF($E49="MENSUAL",$D49,IF($E49="TRIMESTRAL",$D49/3,IF($E49="SEMESTRAL",$D49/2,IF($E49="ANUAL",$D49/12,IF($E49="BIMENSUAL",$D49/2))))),0) -> 25.833333 | N49: NO | O49: =IF($N49="NO",IF($E49="MENSUAL",$D49,IF($E49="TRIMESTRAL",$D49/3,IF($E49="SEMESTRAL",$D49/2,IF($E49="ANUAL",$D49/12,IF($E49="BIMENSUAL",$D49/2))))),0) -> 25.833333 | Q49: NO | R49: =IF($Q49="NO",IF($E49="MENSUAL",$D49,IF($E49="TRIMESTRAL",$D49/3,IF($E49="SEMESTRAL",$D49/2,IF($E49="ANUAL",$D49/12,IF($E49="BIMENSUAL",$D49/2))))),0) -> 25.833333 | T49: NO | U49: =IF($T49="NO",IF($E49="MENSUAL",$D49,IF($E49="TRIMESTRAL",$D49/3,IF($E49="SEMESTRAL",$D49/2,IF($E49="ANUAL",$D49/12,IF($E49="BIMENSUAL",$D49/2))))),0) -> 25.833333
A50: GIPUZKOAKO URAK | B50: SANTANDER | C50: CASA | D50: 120 | E50: TRIMESTRAL | F50: =IF($E50="MENSUAL",$D50,IF($E50="TRIMESTRAL",$D50/3,IF($E50="SEMESTRAL",$D50/2,IF($E50="ANUAL",$D50/12,IF($E50="BIMENSUAL",$D50/2))))) -> 40 | H50: NO | I50: =IF($H50="NO",IF($E50="MENSUAL",$D50,IF($E50="TRIMESTRAL",$D50/3,IF($E50="SEMESTRAL",$D50/2,IF($E50="ANUAL",$D50/12,IF($E50="BIMENSUAL",$D50/2))))),0) -> 40 | K50: NO | L50: =IF($H50="NO",IF($E50="MENSUAL",$D50,IF($E50="TRIMESTRAL",$D50/3,IF($E50="SEMESTRAL",$D50/2,IF($E50="ANUAL",$D50/12,IF($E50="BIMENSUAL",$D50/2))))),0) -> 40 | N50: NO | O50: =IF($N50="NO",IF($E50="MENSUAL",$D50,IF($E50="TRIMESTRAL",$D50/3,IF($E50="SEMESTRAL",$D50/2,IF($E50="ANUAL",$D50/12,IF($E50="BIMENSUAL",$D50/2))))),0) -> 40 | Q50: NO | R50: =IF($Q50="NO",IF($E50="MENSUAL",$D50,IF($E50="TRIMESTRAL",$D50/3,IF($E50="SEMESTRAL",$D50/2,IF($E50="ANUAL",$D50/12,IF($E50="BIMENSUAL",$D50/2))))),0) -> 40 | T50: NO | U50: =IF($T50="NO",IF($E50="MENSUAL",$D50,IF($E50="TRIMESTRAL",$D50/3,IF($E50="SEMESTRAL",$D50/2,IF($E50="ANUAL",$D50/12,IF($E50="BIMENSUAL",$D50/2))))),0) -> 40
A51: GAS (Total Energies) | B51: SANTANDER | C51: CASA | D51: 150 | E51: BIMENSUAL | F51: =IF($E51="MENSUAL",$D51,IF($E51="TRIMESTRAL",$D51/3,IF($E51="SEMESTRAL",$D51/2,IF($E51="ANUAL",$D51/12,IF($E51="BIMENSUAL",$D51/2))))) -> 75 | H51: NO | I51: =IF($H51="NO",IF($E51="MENSUAL",$D51,IF($E51="TRIMESTRAL",$D51/3,IF($E51="SEMESTRAL",$D51/2,IF($E51="ANUAL",$D51/12,IF($E51="BIMENSUAL",$D51/2))))),0) -> 75 | K51: NO | L51: =IF($H51="NO",IF($E51="MENSUAL",$D51,IF($E51="TRIMESTRAL",$D51/3,IF($E51="SEMESTRAL",$D51/2,IF($E51="ANUAL",$D51/12,IF($E51="BIMENSUAL",$D51/2))))),0) -> 75 | N51: NO | O51: =IF($N51="NO",IF($E51="MENSUAL",$D51,IF($E51="TRIMESTRAL",$D51/3,IF($E51="SEMESTRAL",$D51/2,IF($E51="ANUAL",$D51/12,IF($E51="BIMENSUAL",$D51/2))))),0) -> 75 | Q51: NO | R51: =IF($Q51="NO",IF($E51="MENSUAL",$D51,IF($E51="TRIMESTRAL",$D51/3,IF($E51="SEMESTRAL",$D51/2,IF($E51="ANUAL",$D51/12,IF($E51="BIMENSUAL",$D51/2))))),0) -> 75 | T51: NO | U51: =IF($T51="NO",IF($E51="MENSUAL",$D51,IF($E51="TRIMESTRAL",$D51/3,IF($E51="SEMESTRAL",$D51/2,IF($E51="ANUAL",$D51/12,IF($E51="BIMENSUAL",$D51/2))))),0) -> 75
A52: IBERDROLA (CUNENERGIA) | B52: SANTANDER | C52: CASA | D52: 70 | E52: MENSUAL | F52: =IF($E52="MENSUAL",$D52,IF($E52="TRIMESTRAL",$D52/3,IF($E52="SEMESTRAL",$D52/2,IF($E52="ANUAL",$D52/12,IF($E52="BIMENSUAL",$D52/2))))) -> 70 | H52: NO | I52: =IF($H52="NO",IF($E52="MENSUAL",$D52,IF($E52="TRIMESTRAL",$D52/3,IF($E52="SEMESTRAL",$D52/2,IF($E52="ANUAL",$D52/12,IF($E52="BIMENSUAL",$D52/2))))),0) -> 70 | K52: NO | L52: =IF($H52="NO",IF($E52="MENSUAL",$D52,IF($E52="TRIMESTRAL",$D52/3,IF($E52="SEMESTRAL",$D52/2,IF($E52="ANUAL",$D52/12,IF($E52="BIMENSUAL",$D52/2))))),0) -> 70 | N52: NO | O52: =IF($N52="NO",IF($E52="MENSUAL",$D52,IF($E52="TRIMESTRAL",$D52/3,IF($E52="SEMESTRAL",$D52/2,IF($E52="ANUAL",$D52/12,IF($E52="BIMENSUAL",$D52/2))))),0) -> 70 | Q52: NO | R52: =IF($Q52="NO",IF($E52="MENSUAL",$D52,IF($E52="TRIMESTRAL",$D52/3,IF($E52="SEMESTRAL",$D52/2,IF($E52="ANUAL",$D52/12,IF($E52="BIMENSUAL",$D52/2))))),0) -> 70 | T52: NO | U52: =IF($T52="NO",IF($E52="MENSUAL",$D52,IF($E52="TRIMESTRAL",$D52/3,IF($E52="SEMESTRAL",$D52/2,IF($E52="ANUAL",$D52/12,IF($E52="BIMENSUAL",$D52/2))))),0) -> 70
A53: EUSKALTEL | B53: SANTANDER | C53: CASA | D53: 80 | E53: MENSUAL | F53: =IF($E53="MENSUAL",$D53,IF($E53="TRIMESTRAL",$D53/3,IF($E53="SEMESTRAL",$D53/2,IF($E53="ANUAL",$D53/12,IF($E53="BIMENSUAL",$D53/2))))) -> 80 | H53: NO | I53: =IF($H53="NO",IF($E53="MENSUAL",$D53,IF($E53="TRIMESTRAL",$D53/3,IF($E53="SEMESTRAL",$D53/2,IF($E53="ANUAL",$D53/12,IF($E53="BIMENSUAL",$D53/2))))),0) -> 80 | K53: NO | L53: =IF($H53="NO",IF($E53="MENSUAL",$D53,IF($E53="TRIMESTRAL",$D53/3,IF($E53="SEMESTRAL",$D53/2,IF($E53="ANUAL",$D53/12,IF($E53="BIMENSUAL",$D53/2))))),0) -> 80 | N53: NO | O53: =IF($N53="NO",IF($E53="MENSUAL",$D53,IF($E53="TRIMESTRAL",$D53/3,IF($E53="SEMESTRAL",$D53/2,IF($E53="ANUAL",$D53/12,IF($E53="BIMENSUAL",$D53/2))))),0) -> 80 | Q53: NO | R53: =IF($Q53="NO",IF($E53="MENSUAL",$D53,IF($E53="TRIMESTRAL",$D53/3,IF($E53="SEMESTRAL",$D53/2,IF($E53="ANUAL",$D53/12,IF($E53="BIMENSUAL",$D53/2))))),0) -> 80 | T53: NO | U53: =IF($T53="NO",IF($E53="MENSUAL",$D53,IF($E53="TRIMESTRAL",$D53/3,IF($E53="SEMESTRAL",$D53/2,IF($E53="ANUAL",$D53/12,IF($E53="BIMENSUAL",$D53/2))))),0) -> 80
A54: ESTUDIOS AMAIA | B54: SANTANDER | C54: ESTUDIOS | D54: 1300 | E54: ANUAL | F54: =IF($E54="MENSUAL",$D54,IF($E54="TRIMESTRAL",$D54/3,IF($E54="SEMESTRAL",$D54/2,IF($E54="ANUAL",$D54/12,IF($E54="BIMENSUAL",$D54/2))))) -> 108.33333 | H54: NO | I54: =IF($H54="NO",IF($E54="MENSUAL",$D54,IF($E54="TRIMESTRAL",$D54/3,IF($E54="SEMESTRAL",$D54/2,IF($E54="ANUAL",$D54/12,IF($E54="BIMENSUAL",$D54/2))))),0) -> 108.33333 | K54: NO | L54: =IF($H54="NO",IF($E54="MENSUAL",$D54,IF($E54="TRIMESTRAL",$D54/3,IF($E54="SEMESTRAL",$D54/2,IF($E54="ANUAL",$D54/12,IF($E54="BIMENSUAL",$D54/2))))),0) -> 108.33333 | N54: SI | O54: =IF($N54="NO",IF($E54="MENSUAL",$D54,IF($E54="TRIMESTRAL",$D54/3,IF($E54="SEMESTRAL",$D54/2,IF($E54="ANUAL",$D54/12,IF($E54="BIMENSUAL",$D54/2))))),0) -> 0 | Q54: NO | R54: =IF($Q54="NO",IF($E54="MENSUAL",$D54,IF($E54="TRIMESTRAL",$D54/3,IF($E54="SEMESTRAL",$D54/2,IF($E54="ANUAL",$D54/12,IF($E54="BIMENSUAL",$D54/2))))),0) -> 108.33333 | T54: NO | U54: =IF($T54="NO",IF($E54="MENSUAL",$D54,IF($E54="TRIMESTRAL",$D54/3,IF($E54="SEMESTRAL",$D54/2,IF($E54="ANUAL",$D54/12,IF($E54="BIMENSUAL",$D54/2))))),0) -> 108.33333
A55: ESTUDIOS OLATZ | B55: SANTANDER | C55: ESTUDIOS | D55: 1800 | E55: ANUAL | F55: =IF($E55="MENSUAL",$D55,IF($E55="TRIMESTRAL",$D55/3,IF($E55="SEMESTRAL",$D55/2,IF($E55="ANUAL",$D55/12,IF($E55="BIMENSUAL",$D55/2))))) -> 150 | H55: NO | I55: =IF($H55="NO",IF($E55="MENSUAL",$D55,IF($E55="TRIMESTRAL",$D55/3,IF($E55="SEMESTRAL",$D55/2,IF($E55="ANUAL",$D55/12,IF($E55="BIMENSUAL",$D55/2))))),0) -> 150 | K55: NO | L55: =IF($H55="NO",IF($E55="MENSUAL",$D55,IF($E55="TRIMESTRAL",$D55/3,IF($E55="SEMESTRAL",$D55/2,IF($E55="ANUAL",$D55/12,IF($E55="BIMENSUAL",$D55/2))))),0) -> 150 | N55: SI | O55: =IF($N55="NO",IF($E55="MENSUAL",$D55,IF($E55="TRIMESTRAL",$D55/3,IF($E55="SEMESTRAL",$D55/2,IF($E55="ANUAL",$D55/12,IF($E55="BIMENSUAL",$D55/2))))),0) -> 0 | Q55: NO | R55: =IF($Q55="NO",IF($E55="MENSUAL",$D55,IF($E55="TRIMESTRAL",$D55/3,IF($E55="SEMESTRAL",$D55/2,IF($E55="ANUAL",$D55/12,IF($E55="BIMENSUAL",$D55/2))))),0) -> 150 | T55: NO | U55: =IF($T55="NO",IF($E55="MENSUAL",$D55,IF($E55="TRIMESTRAL",$D55/3,IF($E55="SEMESTRAL",$D55/2,IF($E55="ANUAL",$D55/12,IF($E55="BIMENSUAL",$D55/2))))),0) -> 150
...

Sheet MINIMOS
B1: ENERO | C1: FEBRERO | D1: MARZO | E1: ABRIL | F1: MAYO | G1: JUNIO | H1: JULIO | I1: AGOSTO | J1: SEPTIEMBRE | K1: OCTUBRE | L1: NOVIEMBRE | M1: DICIEMBRE
A2: MES TERMINADO | B2: Sí | C2: Sí | D2: Sí | E2: Sí | F2: Sí | G2: Sí | H2: Sí | I2: Sí | J2: No | K2: No | L2: No | M2: No
A4: GASTO PREVISTO MES SANTANDER TIPO 1 | B4: 0 | C4: 0 | D4: 1600 | E4: 2700 | F4: 0 | G4: 1300 | H4: 1000 | I4: 0 | J4: 0 | K4: 0 | L4: 0 | M4: 0 | N4: =SUM(B4:M4) -> 6600
A5: ---- GASTOS ASOCIADOS A SANTANDER 1 | B5: ='GASTOS '!E131 -> 345.24 | C5: ='GASTOS '!K131 -> 0 | D5: ='GASTOS '!Q131 -> 1606 | E5: ='GASTOS '!W131 -> 2700 | F5: ='GASTOS '!AC131 -> 119.25 | G5: ='GASTOS '!AI131 -> 1338.3 | H5: ='GASTOS '!AO131 -> 1188.09 | I5: ='GASTOS '!AU131 -> 0 | J5: ='GASTOS '!BO131 -> 0 | K5: ='GASTOS '!BG131 -> 0 | L5: ='GASTOS '!BM131 -> 0 | M5: ='GASTOS '!BS131 -> 0 | N5: =SUM(B5:M5) -> 7296.88
A6: BALANCE GASTOS SANTANDER 1 | B6: =B4-B5 -> -345.24 | C6: =C4-C5 -> 0 | D6: =D4-D5 -> -6 | E6: =E4-E5 -> 0 | F6: =F4-F5 -> -119.25 | G6: =G4-G5 -> -38.3 | H6: =H4-H5 -> -188.09 | I6: =I4-I5 -> 0 | ... M6: =M4-M5 -> 0 | N6: =SUM(B6:M6) -> -696.88
A8: GASTO PREVISTO MES SANTANDER TIPO 2 | B8: =$N$9/12 -> 2513.2492 | C8: =$N$9/12 -> 2513.2492 | D8: =$N$9/12 -> 2513.2492 | E8: =$N$9/12 -> 2513.2492 | F8: =$N$9/12 -> 2513.2492 | G8: =$N$9/12 -> 2513.2492 | H8: =$N$9/12 -> 2513.2492 | I8: =$N$9/12 -> 2513.2492 | ... M8: =$N$9/12 -> 2513.2492 | N8: =SUM(B8:M8) -> 30158.99
A9: ---- GASTOS ASOCIADOS A SANTANDER | B9: ='AÑO 2026'!F99 -> 2696.4 | C9: ='AÑO 2026'!G99 -> 1338.15 | D9: ='AÑO 2026'!H99 -> 2565.99 | E9: ='AÑO 2026'!I99 -> 2296.97 | F9: ='AÑO 2026'!J99 -> 2353.37 | G9: ='AÑO 2026'!K99 -> 2797.81 | H9: ='AÑO 2026'!L99 -> 2189.34 | I9: ='AÑO 2026'!M99 -> 2340.51 | ... M9: ='AÑO 2026'!Q99 -> 4080.67 | N9: =SUM(B9:M9) -> 30158.99 | O9: Esta incluido el traspaso a N26
A10: CONTROL GASTOS SANTANDER (1.835€/MES) | B10: =B8-B9 -> -183.15083 | C10: =C8-C9 -> 1175.0992 | D10: =D8-D9 -> -52.740833 | E10: =E8-E9 -> 216.27917 | F10: =F8-F9 -> 159.87917 | G10: =G8-G9 -> -284.56083 | H10: =H8-H9 -> 323.90917 | I10: =I8-I9 -> 172.73917 | ... M10: =M8-M9 -> -1567.4208 | N10: =SUM(B10:M10) -> -2.2737368e-12
A12: GASTO PREVISTO MES KUTXA TIPO 1 | B12: 1400 | C12: 1400 | D12: 1400 | E12: 1400 | F12: 1400 | G12: 1400 | H12: 1400 | I12: 1400 | J12: 1400 | K12: 1400 | L12: 1400 | M12: 1400 | N12: =SUM(B12:M12) -> 16800
A13: ---- GASTOS ASOCIADOS A KUTXA 1 | B13: ='GASTOS '!E130 -> 1169.85 | C13: ='GASTOS '!K130 -> 1918.47 | D13: ='GASTOS '!Q130 -> 1667.22 | E13: ='GASTOS '!W130 -> 1967.94 | F13: ='GASTOS '!AC130 -> 2295.85 | G13: ='GASTOS '!AI130 -> 1749.47 | H13: ='GASTOS '!AO130 -> 2025.87 | I13: ='GASTOS '!AU130 -> 1626.91 | J13: ='GASTOS '!BA130 -> 0 | K13: ='GASTOS '!BG130 -> 0 | L13: ='GASTOS '!BM130 -> 0 | M13: ='GASTOS '!BS130 -> 0 | N13: =SUM(B13:M13) -> 14421.58
A14: BALANCE GASTOS KUTXA 1 (1.400€/MES) | B14: =B12-B13 -> 230.15 | C14: =C12-C13 -> -518.47 | D14: =D12-D13 -> -267.22 | E14: =E12-E13 -> -567.94 | F14: =F12-F13 -> -895.85 | G14: =G12-G13 -> -349.47 | H14: =H12-H13 -> -625.87 | I14: =I12-I13 -> -226.91 | ... M14: =M12-M13 -> 1400 | N14: =SUM(B14:M14) -> 2378.42
B15: =SUM(B13)/1 -> 1169.85 | C15: {=SUM(B13:C13/2)} -> 1544.16 | D15: =SUM(B13:D13)/3 -> 1585.18 | E15: =SUM(B13:E13)/4 -> 1680.87 | F15: =SUM(B13:F13)/5 -> 1803.866 | G15: =SUM(B13:G13)/6 -> 1794.8 | H15: =SUM(B13:H13)/7 -> 1827.81 | I15: =SUM(B13:I13)/8 -> 1802.6975 | J15: =SUM(B13:J13)/9 -> 1602.3978 | K15: =SUM(B13:K13)/10 -> 1442.158 | L15: =SUM(B13:L13)/11 -> 1311.0527 | M15: =SUM(B13:M13)/12 -> 1201.7983
A16: GASTO PREVISTO MES KUTXA TIPO 2 | B16: =$N$17/12 -> 991.375 | C16: =$N$17/12 -> 991.375 | D16: =$N$17/12 -> 991.375 | E16: =$N$17/12 -> 991.375 | F16: =$N$17/12 -> 991.375 | G16: =$N$17/12 -> 991.375 | H16: =$N$17/12 -> 991.375 | I16: =$N$17/12 -> 991.375 | ... M16: =$N$17/12 -> 991.375 | N16: =SUM(B16:M16) -> 11896.5
A17: ---- GASTOS ASOCIADOS A KUTXA 2 | B17: ='AÑO 2026'!F122 -> 1049.04 | C17: ='AÑO 2026'!G122 -> 1273.18 | D17: ='AÑO 2026'!H122 -> 852.75 | E17: ='AÑO 2026'!I122 -> 1069.95 | F17: ='AÑO 2026'!J122 -> 1088.46 | G17: ='AÑO 2026'!K122 -> 944.52 | H17: ='AÑO 2026'!L122 -> 886.57 | I17: ='AÑO 2026'!M122 -> 954.16 | ... M17: ='AÑO 2026'!Q122 -> 1129.7 | N17: =SUM(B17:M17) -> 11896.5
A18: BALANCE GASTOS KUTXA 2 (1.000€/MES) | B18: =B16-B17 -> -57.665 | C18: =C16-C17 -> -281.805 | D18: =D16-D17 -> 138.625 | E18: =E16-E17 -> -78.575 | F18: =F16-F17 -> -97.085 | G18: =G16-G17 -> 46.855 | H18: =H16-H17 -> 104.805 | I18: =I16-I17 -> 37.215 | ... M18: =M16-M17 -> -138.325 | N18: =SUM(B18:M18) -> 5.6843419e-13
B19: =SUM(B17)/1 -> 1049.04 | C19: {=SUM(B17:C17/2)} -> 1161.11 | D19: =SUM(B17:D17)/3 -> 1058.3233 | E19: =SUM(B17:E17)/4 -> 1061.23 | F19: =SUM(B17:F17)/5 -> 1066.676 | G19: =SUM(B17:G17)/6 -> 1046.3167 | H19: =SUM(B17:H17)/7 -> 1023.4957 | I19: =SUM(B17:I17)/8 -> 1014.8287 | J19: =SUM(B17:J17)/9 -> 988.70333 | K19: =SUM(B17:K17)/10 -> 995.842 | L19: =SUM(B17:L17)/11 -> 978.8 | M19: =SUM(B17:M17)/12 -> 991.375
A20: GASTO PREVISTO MES N26 TIPO 1 | B20: 500 | C20: 500 | D20: 500 | E20: 500 | F20: 500 | G20: 500 | H20: 500 | I20: 500 | J20: 500 | K20: 500 | L20: 500 | M20: 500 | N20: =SUM(B20:M20) -> 6000
A21: ---- GASTOS ASOCIADOS A N26 | B21: ='GASTOS '!E129 -> 0 | C21: ='GASTOS '!K129 -> 192 | D21: ='GASTOS '!Q129 -> 140 | E21: ='GASTOS '!W129 -> 0 | F21: ='GASTOS '!AC129 -> 185 | G21: ='GASTOS '!AI129 -> 0 | H21: ='GASTOS '!AO129 -> 127 | I21: ='GASTOS '!AU129 -> 0 | J21: ='GASTOS '!BA129 -> 500 | K21: ='GASTOS '!BG129 -> 500 | L21: ='GASTOS '!BM129 -> 500 | M21: ='GASTOS '!BS129 -> 500 | N21: =SUM(B21:M21) -> 2644
A22: BALANCE GASTOS N26 (500€/MES) | B22: =B20-B21 -> 500 | C22: =C20-C21 -> 308 | D22: =D20-D21 -> 360 | E22: =E20-E21 -> 500 | F22: =F20-F21 -> 315 | G22: =G20-G21 -> 500 | H22: =H20-H21 -> 373 | I22: =I20-I21 -> 500 | ... M22: =M20-M21 -> 0 | N22: =SUM(B22:M22) -> 3356
B23: =SUM(B21)/1 -> 0 | C23: {=SUM(B21:C21/2)} -> 96 | D23: =SUM(B21:D21)/3 -> 110.66667 | E23: =SUM(B21:E21)/4 -> 83 | F23: =SUM(B21:F21)/5 -> 103.4 | G23: =SUM(B21:G21)/6 -> 86.166667 | H23: =SUM(B21:H21)/7 -> 92 | I23: =SUM(B21:I21)/8 -> 80.5 | J23: =SUM(B21:J21)/9 -> 127.11111 | K23: =SUM(B21:K21)/10 -> 164.4 | L23: =SUM(B21:L21)/11 -> 194.90909 | M23: =SUM(B21:M21)/12 -> 220.33333
N24: GASTO ACTUAL | O24: GASTO PREVISTO | P24: INGRESOS | Q24: GASTO PENDIENTE | R24: AHORRO
A25: GASTOS ASOCIADOS A SANTANDER (TIPO 1 + TIPO 2) | B25: =B5+IF(B2="Sí",B9,0) -> 3041.64 | C25: =C5+IF(C2="Sí",C9,0) -> 1338.15 | D25: =D5+IF(D2="Sí",D9,0) -> 4171.99 | E25: =E5+IF(E2="Sí",E9,0) -> 4996.97 | F25: =F5+IF(F2="Sí",F9,0) -> 2472.62 | G25: =G5+IF(G2="Sí",G9,0) -> 4136.11 | H25: =H5+IF(H2="Sí",H9,0) -> 3377.43 | I25: =I5+IF(I2="Sí",I9,0) -> 2340.51 | ... M25: =M5+IF(M2="Sí",M9,0) -> 0 | N25: =SUM(B25:M25) -> 25875.42 | O25: =N4+N8 -> 36758.99 | P25: ='AÑO 2026'!S33 -> 35499.24 | Q25: =N8-N25 -> 4283.57 | R25: =P25-O25 -> -1259.75
